Workbook

Sheet Data
A1: Item Name | B1: Item Code | C1: Category | D1: UOM | E1: Cost Price | F1: Sell Price | G1: Location | H1: Barcode | I1: SR1 | J1: SR2 | K1: SR3 | L1: Batch Number | M1: Production Date | N1: Expiry Date | O1: Adjustment Type | P1: Adjustmentqty | Q1: =A1 -> Item Name
A2: Item 001 | B2: ITM0001 | C2: GMA | D2: kg | E2: 100 | F2: 100 | G2: Storage A@A-1@B-1@L-1 | H2: 890000000001 | I2: SR4040 | J2: SR8173 | K2: SR4875 | L2: BN00001 | M2: 45624 | N2: 46171 | O2: Addition | P2: 10 | Q2: =A2 -> Item 001
A3: Item 002 | B3: ITM0002 | C3: Gear | D3: ml | E3: 100 | F3: 100 | G3: Storage A@A-1@B-1@L-2 | H3: 890000000002 | I3: SR6105 | J3: SR3673 | K3: SR2571 | L3: BN00002 | M3: 45625 | N3: 46171 | O3: Addition | P3: 10 | Q3: =A3 -> Item 002
A4: Item 003 | B4: ITM0003 | C4: Parts | D4: 12 | E4: 100 | F4: 100 | G4: Storage A@A-2@B-3@L-3 | H4: 890000000003 | I4: SR1419 | J4: SR9508 | K4: SR7676 | L4: BN00003 | M4: 45626 | N4: 46171 | O4: Addition | P4: 10 | Q4: =A4 -> Item 003
A5: Item 004 | B5: ITM0004 | C5: Vehicle | D5: 0.22 | E5: 100 | F5: 100 | G5: Storage A@A-1@B-1@L-3 | H5: 890000000004 | I5: SR3458 | J5: SR6595 | K5: SR7838 | L5: BN00004 | M5: 45694 | N5: 46171 | O5: Addition | P5: 10 | Q5: =A5 -> Item 004
A6: Item 005 | B6: ITM0005 | C6: Parts | D6: 12 | E6: 100 | F6: 100 | G6: Storage A@A-2@B-3@L-4 | H6: 890000000005 | I6: SR6439 | J6: SR3122 | K6: SR6930 | L6: BN00005 | M6: 45749 | N6: 46403 | O6: Addition | P6: 10 | Q6: =A6 -> Item 005
A7: Item 006 | B7: ITM0006 | C7: Parts | E7: 100 | F7: 100 | G7: Storage A@A-3@B-5@L-1 | H7: 890000000006 | I7: SR2530 | J7: SR3532 | K7: SR5713 | L7: BN00006 | M7: 45631 | N7: 46642 | O7: Addition | P7: 10 | Q7: =A7 -> Item 006
A8: Item 007 | B8: ITM0007 | C8: Vehicle | D8: #$ | E8: 100 | F8: 100 | G8: Storage A@A-3@B-5@L-2 | H8: 890000000007 | I8: SR5967 | J8: SR9075 | K8: SR9639 | L8: BN00007 | M8: 45649 | N8: 46245 | O8: Addition | P8: 10 | Q8: =A8 -> Item 007
A9: Item 008 | B9: ITM0008 | C9: Gear | D9: %$ | E9: 100 | F9: 100 | G9: Storage A@A-2@B-3@L-5 | H9: 890000000008 | I9: SR9956 | J9: SR1329 | K9: SR7724 | L9: BN00008 | M9: 45806 | N9: 46763 | O9: Addition | P9: 10 | Q9: =A9 -> Item 008
A10: Item 009 | B10: ITM0009 | C10: GMA | D10: w | E10: 100 | F10: 100 | G10: Storage A@A-3@B-5@L-3 | H10: 890000000009 | I10: SR9696 | J10: SR9982 | K10: SR8387 | L10: BN00009 | M10: 45597 | N10: 46206 | O10: Addition | P10: 10 | Q10: =A10 -> Item 009
A11: Item 010 | B11: ITM0010 | C11: Parts | D11: L | E11: 100 | F11: 100 | G11: Storage A@A-2@B-4@L-1 | H11: 890000000010 | I11: SR4801 | J11: SR2682 | K11: SR6051 | L11: BN00010 | M11: 45719 | N11: 46486 | O11: Addition | P11: 10 | Q11: =A11 -> Item 010

Sheet Sheet1

Sheet AUDITOR_MAPPING
A1: Auditor | B1: Category | C1: Storage
A2: dine | B2: Vehicle | C2: Storage A@A-2@B-3@L-4
A3: egggg tttt | B3: Gear | C3: Storage A@A-3@B-5@L-1
A4: dine | B4: GMA | C4: Storage A@A-3@B-5@L-2
A5: egggg tttt | B5: Parts | C5: Storage A@A-2@B-3@L-5

Sheet auditor_1
A1: locations | B1: code | C1: audited | D1: damaged | E1: S.No | F1: auditor | G1: stock | H1: audited | I1: damaged | J1: loss | K1: excess | L1: completed | M1: progress | N1: status
A2: Storage A@A-2@B-3@L-3 | B2: ABC1123 | C2: 10 | D2: 0 | E2: 1 | F2: dine | G2: =IFERROR(VLOOKUP(B2,Data!$B:$P,15,FALSE)*VLOOKUP(B2,Data!$B:$P,4,FALSE),0) -> 0 | H2: =IFERROR(VLOOKUP(B2,Data!$B:$P,4,FALSE)*C2,0) -> 0 | I2: =IFERROR(VLOOKUP(B2,Data!$B:$P,4,FALSE)*D2,0) -> 0 | J2: =IFERROR(MAX(0,(VLOOKUP(B2,Data!$B:$P,15,FALSE)-C2)*VLOOKUP(B2,Data!$B:$P,4,FALSE)),0) -> 0 | K2: =IFERROR(MAX(0,(C2-(VLOOKUP(B2,Data!$B:$P,15,FALSE)))*VLOOKUP(B2,Data!$B:$P,4,FALSE)),0) -> 0 | L2: =IFERROR(IFERROR(IF(0>VLOOKUP(B2,Data!$B:$P,15,FALSE),0,C2),0),0) -> 0
A3: Storage A@A-1@B-1@L-1 | B3: ITM0001 | C3: 10 | D3: 10 | E3: 2 | F3: dine | G3: =IFERROR(VLOOKUP(B3,Data!$B:$P,15,FALSE)*VLOOKUP(B3,Data!$B:$P,4,FALSE),0) -> 1000 | H3: =IFERROR(VLOOKUP(B3,Data!$B:$P,4,FALSE)*C3,0) -> 1000 | I3: =IFERROR(VLOOKUP(B3,Data!$B:$P,4,FALSE)*D3,0) -> 1000 | J3: =IFERROR(MAX(0,(VLOOKUP(B3,Data!$B:$P,15,FALSE)-C3)*VLOOKUP(B3,Data!$B:$P,4,FALSE)),0) -> 0 | K3: =IFERROR(MAX(0,(C3-(VLOOKUP(B3,Data!$B:$P,15,FALSE)))*VLOOKUP(B3,Data!$B:$P,4,FALSE)),0) -> 0 | L3: =IFERROR(IFERROR(IF(0>VLOOKUP(B3,Data!$B:$P,15,FALSE),0,C3),0),0) -> 10
A4: Storage A@A-1@B-1@L-2 | B4: ITM0002 | C4: 10 | D4: 5 | E4: 3 | F4: dine | G4: =IFERROR(VLOOKUP(B4,Data!$B:$P,15,FALSE)*VLOOKUP(B4,Data!$B:$P,4,FALSE),0) -> 1000 | H4: =IFERROR(VLOOKUP(B4,Data!$B:$P,4,FALSE)*C4,0) -> 1000 | I4: =IFERROR(VLOOKUP(B4,Data!$B:$P,4,FALSE)*D4,0) -> 500 | J4: =IFERROR(MAX(0,(VLOOKUP(B4,Data!$B:$P,15,FALSE)-C4)*VLOOKUP(B4,Data!$B:$P,4,FALSE)),0) -> 0 | K4: =IFERROR(MAX(0,(C4-(VLOOKUP(B4,Data!$B:$P,15,FALSE)))*VLOOKUP(B4,Data!$B:$P,4,FALSE)),0) -> 0 | L4: =IFERROR(IFERROR(IF(0>VLOOKUP(B4,Data!$B:$P,15,FALSE),0,C4),0),0) -> 10
A5: Storage A@A-2@B-3@L-3 | B5: ITM0003 | E5: 4 | F5: dine | G5: =IFERROR(VLOOKUP(B5,Data!$B:$P,15,FALSE)*VLOOKUP(B5,Data!$B:$P,4,FALSE),0) -> 1000 | H5: =IFERROR(VLOOKUP(B5,Data!$B:$P,4,FALSE)*C5,0) -> 0 | I5: =IFERROR(VLOOKUP(B5,Data!$B:$P,4,FALSE)*D5,0) -> 0 | J5: =IFERROR(MAX(0,(VLOOKUP(B5,Data!$B:$P,15,FALSE)-C5)*VLOOKUP(B5,Data!$B:$P,4,FALSE)),0) -> 1000 | K5: =IFERROR(MAX(0,(C5-(VLOOKUP(B5,Data!$B:$P,15,FALSE)))*VLOOKUP(B5,Data!$B:$P,4,FALSE)),0) -> 0 | L5: =IFERROR(IFERROR(IF(0>VLOOKUP(B5,Data!$B:$P,15,FALSE),0,C5),0),0) -> 0
A6: Storage A@A-1@B-1@L-3 | B6: ITM0004 | C6: 5 | E6: 5 | F6: dine | G6: =IFERROR(VLOOKUP(B6,Data!$B:$P,15,FALSE)*VLOOKUP(B6,Data!$B:$P,4,FALSE),0) -> 1000 | H6: =IFERROR(VLOOKUP(B6,Data!$B:$P,4,FALSE)*C6,0) -> 500 | I6: =IFERROR(VLOOKUP(B6,Data!$B:$P,4,FALSE)*D6,0) -> 0 | J6: =IFERROR(MAX(0,(VLOOKUP(B6,Data!$B:$P,15,FALSE)-C6)*VLOOKUP(B6,Data!$B:$P,4,FALSE)),0) -> 500 | K6: =IFERROR(MAX(0,(C6-(VLOOKUP(B6,Data!$B:$P,15,FALSE)))*VLOOKUP(B6,Data!$B:$P,4,FALSE)),0) -> 0 | L6: =IFERROR(IFERROR(IF(0>VLOOKUP(B6,Data!$B:$P,15,FALSE),0,C6),0),0) -> 5
A7: Storage A@A-2@B-3@L-4 | B7: ITM0005 | C7: 10 | D7: 5 | E7: 6 | F7: dine | G7: =IFERROR(VLOOKUP(B7,Data!$B:$P,15,FALSE)*VLOOKUP(B7,Data!$B:$P,4,FALSE),0) -> 1000 | H7: =IFERROR(VLOOKUP(B7,Data!$B:$P,4,FALSE)*C7,0) -> 1000 | I7: =IFERROR(VLOOKUP(B7,Data!$B:$P,4,FALSE)*D7,0) -> 500 | J7: =IFERROR(MAX(0,(VLOOKUP(B7,Data!$B:$P,15,FALSE)-C7)*VLOOKUP(B7,Data!$B:$P,4,FALSE)),0) -> 0 | K7: =IFERROR(MAX(0,(C7-(VLOOKUP(B7,Data!$B:$P,15,FALSE)))*VLOOKUP(B7,Data!$B:$P,4,FALSE)),0) -> 0 | L7: =IFERROR(IFERROR(IF(0>VLOOKUP(B7,Data!$B:$P,15,FALSE),0,C7),0),0) -> 10

Sheet auditor_2
A1: locations | B1: code | C1: audited | D1: damaged | E1: S.No | F1: auditor | G1: stock | H1: audited | I1: damaged | J1: loss | K1: excess | L1: completed | M1: progress | N1: status
A2: Storage A@A-2@B-3@L-3 | B2: ABC11234 | C2: 10 | D2: 0 | E2: 7 | F2: egggg tttt | G2: =IFERROR(VLOOKUP(B2,Data!$B:$P,15,FALSE)*VLOOKUP(B2,Data!$B:$P,4,FALSE),0) -> 0 | H2: =IFERROR(VLOOKUP(B2,Data!$B:$P,4,FALSE)*C2,0) -> 0 | I2: =IFERROR(VLOOKUP(B2,Data!$B:$P,4,FALSE)*D2,0) -> 0 | J2: =IFERROR(MAX(0,(VLOOKUP(B2,Data!$B:$P,15,FALSE)-C2)*VLOOKUP(B2,Data!$B:$P,4,FALSE)),0) -> 0 | K2: =IFERROR(MAX(0,(C2-(VLOOKUP(B2,Data!$B:$P,15,FALSE)))*VLOOKUP(B2,Data!$B:$P,4,FALSE)),0) -> 0 | L2: =IFERROR(IFERROR(IF(0>VLOOKUP(B2,Data!$B:$P,15,FALSE),0,C2),0),0) -> 0
A3: Storage A@A-3@B-5@L-1 | B3: ITM0006 | C3: 10.1212 | D3: 1 | E3: 8 | F3: egggg tttt | G3: =IFERROR(VLOOKUP(B3,Data!$B:$P,15,FALSE)*VLOOKUP(B3,Data!$B:$P,4,FALSE),0) -> 1000 | H3: =IFERROR(VLOOKUP(B3,Data!$B:$P,4,FALSE)*C3,0) -> 1012.12 | I3: =IFERROR(VLOOKUP(B3,Data!$B:$P,4,FALSE)*D3,0) -> 100 | J3: =IFERROR(MAX(0,(VLOOKUP(B3,Data!$B:$P,15,FALSE)-C3)*VLOOKUP(B3,Data!$B:$P,4,FALSE)),0) -> 0 | K3: =IFERROR(MAX(0,(C3-(VLOOKUP(B3,Data!$B:$P,15,FALSE)))*VLOOKUP(B3,Data!$B:$P,4,FALSE)),0) -> 12.12 | L3: =IFERROR(IFERROR(IF(0>VLOOKUP(B3,Data!$B:$P,15,FALSE),0,C3),0),0) -> 10.1212
A4: Storage A@A-3@B-5@L-2 | B4: ITM0007 | C4: 12.122 | D4: 0.2129 | E4: 9 | F4: egggg tttt | G4: =IFERROR(VLOOKUP(B4,Data!$B:$P,15,FALSE)*VLOOKUP(B4,Data!$B:$P,4,FALSE),0) -> 1000 | H4: =IFERROR(VLOOKUP(B4,Data!$B:$P,4,FALSE)*C4,0) -> 1212.2 | I4: =IFERROR(VLOOKUP(B4,Data!$B:$P,4,FALSE)*D4,0) -> 21.29 | J4: =IFERROR(MAX(0,(VLOOKUP(B4,Data!$B:$P,15,FALSE)-C4)*VLOOKUP(B4,Data!$B:$P,4,FALSE)),0) -> 0 | K4: =IFERROR(MAX(0,(C4-(VLOOKUP(B4,Data!$B:$P,15,FALSE)))*VLOOKUP(B4,Data!$B:$P,4,FALSE)),0) -> 212.2 | L4: =IFERROR(IFERROR(IF(0>VLOOKUP(B4,Data!$B:$P,15,FALSE),0,C4),0),0) -> 12.122
A5: Storage A@A-2@B-3@L-5 | B5: ITM0008 | C5: 2.21 | D5: 0 | E5: 10 | F5: egggg tttt | G5: =IFERROR(VLOOKUP(B5,Data!$B:$P,15,FALSE)*VLOOKUP(B5,Data!$B:$P,4,FALSE),0) -> 1000 | H5: =IFERROR(VLOOKUP(B5,Data!$B:$P,4,FALSE)*C5,0) -> 221 | I5: =IFERROR(VLOOKUP(B5,Data!$B:$P,4,FALSE)*D5,0) -> 0 | J5: =IFERROR(MAX(0,(VLOOKUP(B5,Data!$B:$P,15,FALSE)-C5)*VLOOKUP(B5,Data!$B:$P,4,FALSE)),0) -> 779 | K5: =IFERROR(MAX(0,(C5-(VLOOKUP(B5,Data!$B:$P,15,FALSE)))*VLOOKUP(B5,Data!$B:$P,4,FALSE)),0) -> 0 | L5: =IFERROR(IFERROR(IF(0>VLOOKUP(B5,Data!$B:$P,15,FALSE),0,C5),0),0) -> 2.21
A6: Storage A@A-3@B-5@L-3 | B6: ITM0009 | C6: 2.33 | D6: 4 | E6: 11 | F6: egggg tttt | G6: =IFERROR(VLOOKUP(B6,Data!$B:$P,15,FALSE)*VLOOKUP(B6,Data!$B:$P,4,FALSE),0) -> 1000 | H6: =IFERROR(VLOOKUP(B6,Data!$B:$P,4,FALSE)*C6,0) -> 233 | I6: =IFERROR(VLOOKUP(B6,Data!$B:$P,4,FALSE)*D6,0) -> 400 | J6: =IFERROR(MAX(0,(VLOOKUP(B6,Data!$B:$P,15,FALSE)-C6)*VLOOKUP(B6,Data!$B:$P,4,FALSE)),0) -> 767 | K6: =IFERROR(MAX(0,(C6-(VLOOKUP(B6,Data!$B:$P,15,FALSE)))*VLOOKUP(B6,Data!$B:$P,4,FALSE)),0) -> 0 | L6: =IFERROR(IFERROR(IF(0>VLOOKUP(B6,Data!$B:$P,15,FALSE),0,C6),0),0) -> 2.33
A7: Storage A@A-2@B-4@L-1 | B7: ITM0010 | E7: 12 | F7: egggg tttt | G7: =IFERROR(VLOOKUP(B7,Data!$B:$P,15,FALSE)*VLOOKUP(B7,Data!$B:$P,4,FALSE),0) -> 1000 | H7: =IFERROR(VLOOKUP(B7,Data!$B:$P,4,FALSE)*C7,0) -> 0 | I7: =IFERROR(VLOOKUP(B7,Data!$B:$P,4,FALSE)*D7,0) -> 0 | J7: =IFERROR(MAX(0,(VLOOKUP(B7,Data!$B:$P,15,FALSE)-C7)*VLOOKUP(B7,Data!$B:$P,4,FALSE)),0) -> 1000 | K7: =IFERROR(MAX(0,(C7-(VLOOKUP(B7,Data!$B:$P,15,FALSE)))*VLOOKUP(B7,Data!$B:$P,4,FALSE)),0) -> 0 | L7: =IFERROR(IFERROR(IF(0>VLOOKUP(B7,Data!$B:$P,15,FALSE),0,C7),0),0) -> 0

Sheet as_table
A1: auditor | B1: stock | C1: audited | D1: damaged | E1: loss | F1: excess | G1: completed | H1: progress | I1: status
A2: dine | B2: =SUMIFS( CHOOSE(COLUMN()-1,auditor_1!$G:$G,auditor_1!$H:$H,auditor_1!$I:$I,auditor_1!$J:$J,auditor_1!$K:$K,auditor_1!$L:$L), auditor_1!$F:$F,$A2 ) -> 5000 | C2: =SUMIFS( CHOOSE(COLUMN()-1,auditor_1!$G:$G,auditor_1!$H:$H,auditor_1!$I:$I,auditor_1!$J:$J,auditor_1!$K:$K,auditor_1!$L:$L), auditor_1!$F:$F,$A2 ) -> 3500 | D2: =SUMIFS( CHOOSE(COLUMN()-1,auditor_1!$G:$G,auditor_1!$H:$H,auditor_1!$I:$I,auditor_1!$J:$J,auditor_1!$K:$K,auditor_1!$L:$L), auditor_1!$F:$F,$A2 ) -> 2000 | E2: =SUMIFS( CHOOSE(COLUMN()-1,auditor_1!$G:$G,auditor_1!$H:$H,auditor_1!$I:$I,auditor_1!$J:$J,auditor_1!$K:$K,auditor_1!$L:$L), auditor_1!$F:$F,$A2 ) -> 1500 | F2: =SUMIFS( CHOOSE(COLUMN()-1,auditor_1!$G:$G,auditor_1!$H:$H,auditor_1!$I:$I,auditor_1!$J:$J,auditor_1!$K:$K,auditor_1!$L:$L), auditor_1!$F:$F,$A2 ) -> 0 | G2: =SUMIFS( CHOOSE(COLUMN()-1,auditor_1!$G:$G,auditor_1!$H:$H,auditor_1!$I:$I,auditor_1!$J:$J,auditor_1!$K:$K,auditor_1!$L:$L), auditor_1!$F:$F,$A2 ) -> 35 | H2: =sheet6!AH3 -> 0.775 | I2: Completed
A3: egggg tttt | B3: =SUMIFS( CHOOSE(COLUMN()-1,auditor_2!$G:$G,auditor_2!$H:$H,auditor_2!$I:$I,auditor_2!$J:$J,auditor_2!$K:$K,auditor_2!$L:$L), auditor_2!$F:$F,$A3 ) -> 5000 | C3: =SUMIFS( CHOOSE(COLUMN()-1,auditor_2!$G:$G,auditor_2!$H:$H,auditor_2!$I:$I,auditor_2!$J:$J,auditor_2!$K:$K,auditor_2!$L:$L), auditor_2!$F:$F,$A3 ) -> 2678.32 | D3: =SUMIFS( CHOOSE(COLUMN()-1,auditor_2!$G:$G,auditor_2!$H:$H,auditor_2!$I:$I,auditor_2!$J:$J,auditor_2!$K:$K,auditor_2!$L:$L), auditor_2!$F:$F,$A3 ) -> 521.29 | E3: =SUMIFS( CHOOSE(COLUMN()-1,auditor_2!$G:$G,auditor_2!$H:$H,auditor_2!$I:$I,auditor_2!$J:$J,auditor_2!$K:$K,auditor_2!$L:$L), auditor_2!$F:$F,$A3 ) -> 2546 | F3: =SUMIFS( CHOOSE(COLUMN()-1,auditor_2!$G:$G,auditor_2!$H:$H,auditor_2!$I:$I,auditor_2!$J:$J,auditor_2!$K:$K,auditor_2!$L:$L), auditor_2!$F:$F,$A3 ) -> 224.32 | G3: =SUMIFS( CHOOSE(COLUMN()-1,auditor_2!$G:$G,auditor_2!$H:$H,auditor_2!$I:$I,auditor_2!$J:$J,auditor_2!$K:$K,auditor_2!$L:$L), auditor_2!$F:$F,$A3 ) -> 26.7832 | H3: =sheet6!AH6 -> 0.651748 | I3: Completed

Sheet auditSummary
A1: Item Code | B1: Item Name | C1: UOM | D1: Stock Quantity | E1: Audited Qty | F1: Variance | G1: Variance Value | H1: Variance Type | I1: Damaged Qty | J1: Auditor Name | M1: Stock Location | N1: Audited Location | O1: Damaged Filter | P1: Location Filter | Q1: filter
A2: =sheet6!B2 -> ITM0010 | B2: =sheet6!C2 -> Item 010 | C2: =IFERROR( IF(VLOOKUP(A2,Data!$B:$P,3,FALSE)="","", VLOOKUP(A2,Data!$B:$P,3,FALSE) ), "") -> L | D2: =IF(sheet6!H2="",0,sheet6!H2) -> 10 | E2: =sheet6!F2 -> 0 | F2: =IF(E2="","", IF(N(D2)=0, E2, E2-D2)) -> -10 | G2: =IFERROR(VLOOKUP(A2,Data!$B:$P,4,FALSE)*F2,0) -> -1000 | H2: =IF(VALUE(F2)<0,"Negative",IF(VALUE(F2)>0,"Positive","-")) -> Negative | I2: =sheet6!G2 -> 0 | J2: =IFERROR(VLOOKUP(A2,Recently_Audit!B:I,4,FALSE),"") | M2: =IFERROR(VLOOKUP(A2,Data!$B:$P,6,FALSE),"") -> Storage A@A-2@B-4@L-1 | N2: =IFERROR(VLOOKUP(A2,Recently_Audit!B:I,8,FALSE),"") | O2: =IF(I2>0,"Damaged Report","") | P2: =IF(M2<>N2,"Location Conflict","") -> Location Conflict | Q2: =IF(AND(TRIM(D2)="",E2>0),"Excess Line Item", IF(AND(D2=0,E2>0),"Excess Line Item", IF(AND(D2>0,E2=0),"Line Items Not Found", IF(D2>E2,"Negative Variance", IF(E2>D2,"Positive Variance", IF(AND(D2<>"",E2<>""),"Matched Line Item","")))))) -> Line Items Not Found
A3: =sheet6!B3 -> ITM0009 | B3: =sheet6!C3 -> Item 009 | C3: =IFERROR( IF(VLOOKUP(A3,Data!$B:$P,3,FALSE)="","", VLOOKUP(A3,Data!$B:$P,3,FALSE) ), "") -> w | D3: =IF(sheet6!H3="",0,sheet6!H3) -> 10 | E3: =sheet6!F3 -> 2.33 | F3: =IF(E3="","", IF(N(D3)=0, E3, E3-D3)) -> -7.67 | G3: =IFERROR(VLOOKUP(A3,Data!$B:$P,4,FALSE)*F3,0) -> -767 | H3: =IF(VALUE(F3)<0,"Negative",IF(VALUE(F3)>0,"Positive","-")) -> Negative | I3: =sheet6!G3 -> 4 | J3: =IFERROR(VLOOKUP(A3,Recently_Audit!B:I,4,FALSE),"") -> egggg tttt | M3: =IFERROR(VLOOKUP(A3,Data!$B:$P,6,FALSE),"") -> Storage A@A-3@B-5@L-3 | N3: =IFERROR(VLOOKUP(A3,Recently_Audit!B:I,8,FALSE),"") -> Storage A@A-3@B-5@L-3 | O3: =IF(I3>0,"Damaged Report","") -> Damaged Report | P3: =IF(M3<>N3,"Location Conflict","") | Q3: =IF(AND(TRIM(D3)="",E3>0),"Excess Line Item", IF(AND(D3=0,E3>0),"Excess Line Item", IF(AND(D3>0,E3=0),"Line Items Not Found", IF(D3>E3,"Negative Variance", IF(E3>D3,"Positive Variance", IF(AND(D3<>"",E3<>""),"Matched Line Item","")))))) -> Negative Variance
A4: =sheet6!B4 -> ITM0008 | B4: =sheet6!C4 -> Item 008 | C4: =IFERROR( IF(VLOOKUP(A4,Data!$B:$P,3,FALSE)="","", VLOOKUP(A4,Data!$B:$P,3,FALSE) ), "") -> %$ | D4: =IF(sheet6!H4="",0,sheet6!H4) -> 10 | E4: =sheet6!F4 -> 2.21 | F4: =IF(E4="","", IF(N(D4)=0, E4, E4-D4)) -> -7.79 | G4: =IFERROR(VLOOKUP(A4,Data!$B:$P,4,FALSE)*F4,0) -> -779 | H4: =IF(VALUE(F4)<0,"Negative",IF(VALUE(F4)>0,"Positive","-")) -> Negative | I4: =sheet6!G4 -> 0 | J4: =IFERROR(VLOOKUP(A4,Recently_Audit!B:I,4,FALSE),"") -> egggg tttt | M4: =IFERROR(VLOOKUP(A4,Data!$B:$P,6,FALSE),"") -> Storage A@A-2@B-3@L-5 | N4: =IFERROR(VLOOKUP(A4,Recently_Audit!B:I,8,FALSE),"") -> Storage A@A-2@B-3@L-5 | O4: =IF(I4>0,"Damaged Report","") | P4: =IF(M4<>N4,"Location Conflict","") | Q4: =IF(AND(TRIM(D4)="",E4>0),"Excess Line Item", IF(AND(D4=0,E4>0),"Excess Line Item", IF(AND(D4>0,E4=0),"Line Items Not Found", IF(D4>E4,"Negative Variance", IF(E4>D4,"Positive Variance", IF(AND(D4<>"",E4<>""),"Matched Line Item","")))))) -> Negative Variance
A5: =sheet6!B5 -> ITM0007 | B5: =sheet6!C5 -> Item 007 | C5: =IFERROR( IF(VLOOKUP(A5,Data!$B:$P,3,FALSE)="","", VLOOKUP(A5,Data!$B:$P,3,FALSE) ), "") -> #$ | D5: =IF(sheet6!H5="",0,sheet6!H5) -> 10 | E5: =sheet6!F5 -> 12.122 | F5: =IF(E5="","", IF(N(D5)=0, E5, E5-D5)) -> 2.122 | G5: =IFERROR(VLOOKUP(A5,Data!$B:$P,4,FALSE)*F5,0) -> 212.2 | H5: =IF(VALUE(F5)<0,"Negative",IF(VALUE(F5)>0,"Positive","-")) -> Positive | I5: =sheet6!G5 -> 0.2129 | J5: =IFERROR(VLOOKUP(A5,Recently_Audit!B:I,4,FALSE),"") -> egggg tttt | M5: =IFERROR(VLOOKUP(A5,Data!$B:$P,6,FALSE),"") -> Storage A@A-3@B-5@L-2 | N5: =IFERROR(VLOOKUP(A5,Recently_Audit!B:I,8,FALSE),"") -> Storage A@A-3@B-5@L-2 | O5: =IF(I5>0,"Damaged Report","") -> Damaged Report | P5: =IF(M5<>N5,"Location Conflict","") | Q5: =IF(AND(TRIM(D5)="",E5>0),"Excess Line Item", IF(AND(D5=0,E5>0),"Excess Line Item", IF(AND(D5>0,E5=0),"Line Items Not Found", IF(D5>E5,"Negative Variance", IF(E5>D5,"Positive Variance", IF(AND(D5<>"",E5<>""),"Matched Line Item","")))))) -> Positive Variance
A6: =sheet6!B6 -> ITM0006 | B6: =sheet6!C6 -> Item 006 | C6: =IFERROR( IF(VLOOKUP(A6,Data!$B:$P,3,FALSE)="","", VLOOKUP(A6,Data!$B:$P,3,FALSE) ), "") | D6: =IF(sheet6!H6="",0,sheet6!H6) -> 10 | E6: =sheet6!F6 -> 10.1212 | F6: =IF(E6="","", IF(N(D6)=0, E6, E6-D6)) -> 0.1212 | G6: =IFERROR(VLOOKUP(A6,Data!$B:$P,4,FALSE)*F6,0) -> 12.12 | H6: =IF(VALUE(F6)<0,"Negative",IF(VALUE(F6)>0,"Positive","-")) -> Positive | I6: =sheet6!G6 -> 1 | J6: =IFERROR(VLOOKUP(A6,Recently_Audit!B:I,4,FALSE),"") -> egggg tttt | M6: =IFERROR(VLOOKUP(A6,Data!$B:$P,6,FALSE),"") -> Storage A@A-3@B-5@L-1 | N6: =IFERROR(VLOOKUP(A6,Recently_Audit!B:I,8,FALSE),"") -> Storage A@A-3@B-5@L-1 | O6: =IF(I6>0,"Damaged Report","") -> Damaged Report | P6: =IF(M6<>N6,"Location Conflict","") | Q6: =IF(AND(TRIM(D6)="",E6>0),"Excess Line Item", IF(AND(D6=0,E6>0),"Excess Line Item", IF(AND(D6>0,E6=0),"Line Items Not Found", IF(D6>E6,"Negative Variance", IF(E6>D6,"Positive Variance", IF(AND(D6<>"",E6<>""),"Matched Line Item","")))))) -> Positive Variance
A7: =sheet6!B7 -> ABC11234 | B7: =sheet6!C7 | C7: =IFERROR( IF(VLOOKUP(A7,Data!$B:$P,3,FALSE)="","", VLOOKUP(A7,Data!$B:$P,3,FALSE) ), "") | D7: =IF(sheet6!H7="",0,sheet6!H7) -> 0 | E7: =sheet6!F7 -> 10 | F7: =IF(E7="","", IF(N(D7)=0, E7, E7-D7)) -> 10 | G7: =IFERROR(VLOOKUP(A7,Data!$B:$P,4,FALSE)*F7,0) -> 0 | H7: =IF(VALUE(F7)<0,"Negative",IF(VALUE(F7)>0,"Positive","-")) -> Positive | I7: =sheet6!G7 -> 0 | J7: =IFERROR(VLOOKUP(A7,Recently_Audit!B:I,4,FALSE),"") -> egggg tttt | M7: =IFERROR(VLOOKUP(A7,Data!$B:$P,6,FALSE),"") | N7: =IFERROR(VLOOKUP(A7,Recently_Audit!B:I,8,FALSE),"") -> Storage A@A-2@B-3@L-3 | O7: =IF(I7>0,"Damaged Report","") | P7: =IF(M7<>N7,"Location Conflict","") -> Location Conflict | Q7: =IF(AND(TRIM(D7)="",E7>0),"Excess Line Item", IF(AND(D7=0,E7>0),"Excess Line Item", IF(AND(D7>0,E7=0),"Line Items Not Found", IF(D7>E7,"Negative Variance", IF(E7>D7,"Positive Variance", IF(AND(D7<>"",E7<>""),"Matched Line Item","")))))) -> Excess Line Item
A8: =sheet6!B8 -> ITM0005 | B8: =sheet6!C8 -> Item 005 | C8: =IFERROR( IF(VLOOKUP(A8,Data!$B:$P,3,FALSE)="","", VLOOKUP(A8,Data!$B:$P,3,FALSE) ), "") -> 12 | D8: =IF(sheet6!H8="",0,sheet6!H8) -> 10 | E8: =sheet6!F8 -> 10 | F8: =IF(E8="","", IF(N(D8)=0, E8, E8-D8)) -> 0 | G8: =IFERROR(VLOOKUP(A8,Data!$B:$P,4,FALSE)*F8,0) -> 0 | H8: =IF(VALUE(F8)<0,"Negative",IF(VALUE(F8)>0,"Positive","-")) -> - | I8: =sheet6!G8 -> 5 | J8: =IFERROR(VLOOKUP(A8,Recently_Audit!B:I,4,FALSE),"") -> dine | M8: =IFERROR(VLOOKUP(A8,Data!$B:$P,6,FALSE),"") -> Storage A@A-2@B-3@L-4 | N8: =IFERROR(VLOOKUP(A8,Recently_Audit!B:I,8,FALSE),"") -> Storage A@A-2@B-3@L-4 | O8: =IF(I8>0,"Damaged Report","") -> Damaged Report | P8: =IF(M8<>N8,"Location Conflict","") | Q8: =IF(AND(TRIM(D8)="",E8>0),"Excess Line Item", IF(AND(D8=0,E8>0),"Excess Line Item", IF(AND(D8>0,E8=0),"Line Items Not Found", IF(D8>E8,"Negative Variance", IF(E8>D8,"Positive Variance", IF(AND(D8<>"",E8<>""),"Matched Line Item","")))))) -> Matched Line Item
A9: =sheet6!B9 -> ITM0004 | B9: =sheet6!C9 -> Item 004 | C9: =IFERROR( IF(VLOOKUP(A9,Data!$B:$P,3,FALSE)="","", VLOOKUP(A9,Data!$B:$P,3,FALSE) ), "") -> 0.22 | D9: =IF(sheet6!H9="",0,sheet6!H9) -> 10 | E9: =sheet6!F9 -> 5 | F9: =IF(E9="","", IF(N(D9)=0, E9, E9-D9)) -> -5 | G9: =IFERROR(VLOOKUP(A9,Data!$B:$P,4,FALSE)*F9,0) -> -500 | H9: =IF(VALUE(F9)<0,"Negative",IF(VALUE(F9)>0,"Positive","-")) -> Negative | I9: =sheet6!G9 -> 0 | J9: =IFERROR(VLOOKUP(A9,Recently_Audit!B:I,4,FALSE),"") -> dine | M9: =IFERROR(VLOOKUP(A9,Data!$B:$P,6,FALSE),"") -> Storage A@A-1@B-1@L-3 | N9: =IFERROR(VLOOKUP(A9,Recently_Audit!B:I,8,FALSE),"") -> Storage A@A-1@B-1@L-3 | O9: =IF(I9>0,"Damaged Report","") | P9: =IF(M9<>N9,"Location Conflict","") | Q9: =IF(AND(TRIM(D9)="",E9>0),"Excess Line Item", IF(AND(D9=0,E9>0),"Excess Line Item", IF(AND(D9>0,E9=0),"Line Items Not Found", IF(D9>E9,"Negative Variance", IF(E9>D9,"Positive Variance", IF(AND(D9<>"",E9<>""),"Matched Line Item","")))))) -> Negative Variance
A10: =sheet6!B10 -> ITM0003 | B10: =sheet6!C10 -> Item 003 | C10: =IFERROR( IF(VLOOKUP(A10,Data!$B:$P,3,FALSE)="","", VLOOKUP(A10,Data!$B:$P,3,FALSE) ), "") -> 12 | D10: =IF(sheet6!H10="",0,sheet6!H10) -> 10 | E10: =sheet6!F10 -> 0 | F10: =IF(E10="","", IF(N(D10)=0, E10, E10-D10)) -> -10 | G10: =IFERROR(VLOOKUP(A10,Data!$B:$P,4,FALSE)*F10,0) -> -1000 | H10: =IF(VALUE(F10)<0,"Negative",IF(VALUE(F10)>0,"Positive","-")) -> Negative | I10: =sheet6!G10 -> 0 | J10: =IFERROR(VLOOKUP(A10,Recently_Audit!B:I,4,FALSE),"") | M10: =IFERROR(VLOOKUP(A10,Data!$B:$P,6,FALSE),"") -> Storage A@A-2@B-3@L-3 | N10: =IFERROR(VLOOKUP(A10,Recently_Audit!B:I,8,FALSE),"") | O10: =IF(I10>0,"Damaged Report","") | P10: =IF(M10<>N10,"Location Conflict","") -> Location Conflict | Q10: =IF(AND(TRIM(D10)="",E10>0),"Excess Line Item", IF(AND(D10=0,E10>0),"Excess Line Item", IF(AND(D10>0,E10=0),"Line Items Not Found", IF(D10>E10,"Negative Variance", IF(E10>D10,"Positive Variance", IF(AND(D10<>"",E10<>""),"Matched Line Item","")))))) -> Line Items Not Found
A11: =sheet6!B11 -> ITM0002 | B11: =sheet6!C11 -> Item 002 | C11: =IFERROR( IF(VLOOKUP(A11,Data!$B:$P,3,FALSE)="","", VLOOKUP(A11,Data!$B:$P,3,FALSE) ), "") -> ml | D11: =IF(sheet6!H11="",0,sheet6!H11) -> 10 | E11: =sheet6!F11 -> 10 | F11: =IF(E11="","", IF(N(D11)=0, E11, E11-D11)) -> 0 | G11: =IFERROR(VLOOKUP(A11,Data!$B:$P,4,FALSE)*F11,0) -> 0 | H11: =IF(VALUE(F11)<0,"Negative",IF(VALUE(F11)>0,"Positive","-")) -> - | I11: =sheet6!G11 -> 5 | J11: =IFERROR(VLOOKUP(A11,Recently_Audit!B:I,4,FALSE),"") -> dine | M11: =IFERROR(VLOOKUP(A11,Data!$B:$P,6,FALSE),"") -> Storage A@A-1@B-1@L-2 | N11: =IFERROR(VLOOKUP(A11,Recently_Audit!B:I,8,FALSE),"") -> Storage A@A-1@B-1@L-2 | O11: =IF(I11>0,"Damaged Report","") -> Damaged Report | P11: =IF(M11<>N11,"Location Conflict","") | Q11: =IF(AND(TRIM(D11)="",E11>0),"Excess Line Item", IF(AND(D11=0,E11>0),"Excess Line Item", IF(AND(D11>0,E11=0),"Line Items Not Found", IF(D11>E11,"Negative Variance", IF(E11>D11,"Positive Variance", IF(AND(D11<>"",E11<>""),"Matched Line Item","")))))) -> Matched Line Item
A12: =sheet6!B12 -> ITM0001 | B12: =sheet6!C12 -> Item 001 | C12: =IFERROR( IF(VLOOKUP(A12,Data!$B:$P,3,FALSE)="","", VLOOKUP(A12,Data!$B:$P,3,FALSE) ), "") -> kg | D12: =IF(sheet6!H12="",0,sheet6!H12) -> 10 | E12: =sheet6!F12 -> 10 | F12: =IF(E12="","", IF(N(D12)=0, E12, E12-D12)) -> 0 | G12: =IFERROR(VLOOKUP(A12,Data!$B:$P,4,FALSE)*F12,0) -> 0 | H12: =IF(VALUE(F12)<0,"Negative",IF(VALUE(F12)>0,"Positive","-")) -> - | I12: =sheet6!G12 -> 10 | J12: =IFERROR(VLOOKUP(A12,Recently_Audit!B:I,4,FALSE),"") -> dine | M12: =IFERROR(VLOOKUP(A12,Data!$B:$P,6,FALSE),"") -> Storage A@A-1@B-1@L-1 | N12: =IFERROR(VLOOKUP(A12,Recently_Audit!B:I,8,FALSE),"") -> Storage A@A-1@B-1@L-1 | O12: =IF(I12>0,"Damaged Report","") -> Damaged Report | P12: =IF(M12<>N12,"Location Conflict","") | Q12: =IF(AND(TRIM(D12)="",E12>0),"Excess Line Item", IF(AND(D12=0,E12>0),"Excess Line Item", IF(AND(D12>0,E12=0),"Line Items Not Found", IF(D12>E12,"Negative Variance", IF(E12>D12,"Positive Variance", IF(AND(D12<>"",E12<>""),"Matched Line Item","")))))) -> Matched Line Item
A13: =sheet6!B13 -> ABC1123 | B13: =sheet6!C13 | C13: =IFERROR( IF(VLOOKUP(A13,Data!$B:$P,3,FALSE)="","", VLOOKUP(A13,Data!$B:$P,3,FALSE) ), "") | D13: =IF(sheet6!H13="",0,sheet6!H13) -> 0 | E13: =sheet6!F13 -> 10 | F13: =IF(E13="","", IF(N(D13)=0, E13, E13-D13)) -> 10 | G13: =IFERROR(VLOOKUP(A13,Data!$B:$P,4,FALSE)*F13,0) -> 0 | H13: =IF(VALUE(F13)<0,"Negative",IF(VALUE(F13)>0,"Positive","-")) -> Positive | I13: =sheet6!G13 -> 0 | J13: =IFERROR(VLOOKUP(A13,Recently_Audit!B:I,4,FALSE),"") -> dine | M13: =IFERROR(VLOOKUP(A13,Data!$B:$P,6,FALSE),"") | N13: =IFERROR(VLOOKUP(A13,Recently_Audit!B:I,8,FALSE),"") -> Storage A@A-2@B-3@L-3 | O13: =IF(I13>0,"Damaged Report","") | P13: =IF(M13<>N13,"Location Conflict","") -> Location Conflict | Q13: =IF(AND(TRIM(D13)="",E13>0),"Excess Line Item", IF(AND(D13=0,E13>0),"Excess Line Item", IF(AND(D13>0,E13=0),"Line Items Not Found", IF(D13>E13,"Negative Variance", IF(E13>D13,"Positive Variance", IF(AND(D13<>"",E13<>""),"Matched Line Item","")))))) -> Excess Line Item
A14: =sheet6!B14 | B14: =sheet6!C14 | C14: =IFERROR(VLOOKUP(A14,Data!$B:$P,3,FALSE),"")
A15: =sheet6!B15 | B15: =sheet6!C15 | C15: =IFERROR(VLOOKUP(A15,Data!$B:$P,3,FALSE),"")

Sheet Recently_Audit
A1: S.No | B1: Item Code | C1: Item Name | D1: UOM | E1: Auditor Name | F1: Audited Qty | G1: Damage Qty | H1: Stock Qty | I1: Audited Location
A2: =IF(B2="","",ROW()-1) -> 1 | B2: =IFERROR(INDEX(sheet6!B:B, MATCH(ROW()-1, sheet6!$K:$K, 0)), "") -> ITM0009 | C2: =IFERROR(INDEX(sheet6!C:C, MATCH(ROW()-1, sheet6!$K:$K, 0)), "") -> Item 009 | D2: =IFERROR(INDEX(sheet6!D:D, MATCH(ROW()-1, sheet6!$K:$K, 0)), "") -> w | E2: =IFERROR(INDEX(sheet6!E:E, MATCH(ROW()-1, sheet6!$K:$K, 0)), "") -> egggg tttt | F2: =IFERROR(INDEX(sheet6!F:F, MATCH(ROW()-1, sheet6!$K:$K, 0)), "") -> 2.33 | G2: =IFERROR(INDEX(sheet6!G:G, MATCH(ROW()-1, sheet6!$K:$K, 0)), "") -> 4 | H2: =IFERROR(INDEX(sheet6!H:H, MATCH(ROW()-1, sheet6!$K:$K, 0)), "") -> 10 | I2: =IFERROR(INDEX(sheet6!I:I, MATCH(ROW()-1, sheet6!$K:$K, 0)), "") -> Storage A@A-3@B-5@L-3
A3: =IF(B3="","",ROW()-1) -> 2 | B3: =IFERROR(INDEX(sheet6!B:B, MATCH(ROW()-1, sheet6!$K:$K, 0)), "") -> ITM0008 | C3: =IFERROR(INDEX(sheet6!C:C, MATCH(ROW()-1, sheet6!$K:$K, 0)), "") -> Item 008 | D3: =IFERROR(INDEX(sheet6!D:D, MATCH(ROW()-1, sheet6!$K:$K, 0)), "") -> %$ | E3: =IFERROR(INDEX(sheet6!E:E, MATCH(ROW()-1, sheet6!$K:$K, 0)), "") -> egggg tttt | F3: =IFERROR(INDEX(sheet6!F:F, MATCH(ROW()-1, sheet6!$K:$K, 0)), "") -> 2.21 | G3: =IFERROR(INDEX(sheet6!G:G, MATCH(ROW()-1, sheet6!$K:$K, 0)), "") -> 0 | H3: =IFERROR(INDEX(sheet6!H:H, MATCH(ROW()-1, sheet6!$K:$K, 0)), "") -> 10 | I3: =IFERROR(INDEX(sheet6!I:I, MATCH(ROW()-1, sheet6!$K:$K, 0)), "") -> Storage A@A-2@B-3@L-5
A4: =IF(B4="","",ROW()-1) -> 3 | B4: =IFERROR(INDEX(sheet6!B:B, MATCH(ROW()-1, sheet6!$K:$K, 0)), "") -> ITM0007 | C4: =IFERROR(INDEX(sheet6!C:C, MATCH(ROW()-1, sheet6!$K:$K, 0)), "") -> Item 007 | D4: =IFERROR(INDEX(sheet6!D:D, MATCH(ROW()-1, sheet6!$K:$K, 0)), "") -> #$ | E4: =IFERROR(INDEX(sheet6!E:E, MATCH(ROW()-1, sheet6!$K:$K, 0)), "") -> egggg tttt | F4: =IFERROR(INDEX(sheet6!F:F, MATCH(ROW()-1, sheet6!$K:$K, 0)), "") -> 12.122 | G4: =IFERROR(INDEX(sheet6!G:G, MATCH(ROW()-1, sheet6!$K:$K, 0)), "") -> 0.2129 | H4: =IFERROR(INDEX(sheet6!H:H, MATCH(ROW()-1, sheet6!$K:$K, 0)), "") -> 10 | I4: =IFERROR(INDEX(sheet6!I:I, MATCH(ROW()-1, sheet6!$K:$K, 0)), "") -> Storage A@A-3@B-5@L-2
A5: =IF(B5="","",ROW()-1) -> 4 | B5: =IFERROR(INDEX(sheet6!B:B, MATCH(ROW()-1, sheet6!$K:$K, 0)), "") -> ITM0006 | C5: =IFERROR(INDEX(sheet6!C:C, MATCH(ROW()-1, sheet6!$K:$K, 0)), "") -> Item 006 | D5: =IFERROR(INDEX(sheet6!D:D, MATCH(ROW()-1, sheet6!$K:$K, 0)), "") -> 0 | E5: =IFERROR(INDEX(sheet6!E:E, MATCH(ROW()-1, sheet6!$K:$K, 0)), "") -> egggg tttt | F5: =IFERROR(INDEX(sheet6!F:F, MATCH(ROW()-1, sheet6!$K:$K, 0)), "") -> 10.1212 | G5: =IFERROR(INDEX(sheet6!G:G, MATCH(ROW()-1, sheet6!$K:$K, 0)), "") -> 1 | H5: =IFERROR(INDEX(sheet6!H:H, MATCH(ROW()-1, sheet6!$K:$K, 0)), "") -> 10 | I5: =IFERROR(INDEX(sheet6!I:I, MATCH(ROW()-1, sheet6!$K:$K, 0)), "") -> Storage A@A-3@B-5@L-1
A6: =IF(B6="","",ROW()-1) -> 5 | B6: =IFERROR(INDEX(sheet6!B:B, MATCH(ROW()-1, sheet6!$K:$K, 0)), "") -> ABC11234 | C6: =IFERROR(INDEX(sheet6!C:C, MATCH(ROW()-1, sheet6!$K:$K, 0)), "") | D6: =IFERROR(INDEX(sheet6!D:D, MATCH(ROW()-1, sheet6!$K:$K, 0)), "") | E6: =IFERROR(INDEX(sheet6!E:E, MATCH(ROW()-1, sheet6!$K:$K, 0)), "") -> egggg tttt | F6: =IFERROR(INDEX(sheet6!F:F, MATCH(ROW()-1, sheet6!$K:$K, 0)), "") -> 10 | G6: =IFERROR(INDEX(sheet6!G:G, MATCH(ROW()-1, sheet6!$K:$K, 0)), "") -> 0 | H6: =IFERROR(INDEX(sheet6!H:H, MATCH(ROW()-1, sheet6!$K:$K, 0)), "") | I6: =IFERROR(INDEX(sheet6!I:I, MATCH(ROW()-1, sheet6!$K:$K, 0)), "") -> Storage A@A-2@B-3@L-3
A7: =IF(B7="","",ROW()-1) -> 6 | B7: =IFERROR(INDEX(sheet6!B:B, MATCH(ROW()-1, sheet6!$K:$K, 0)), "") -> ITM0005 | C7: =IFERROR(INDEX(sheet6!C:C, MATCH(ROW()-1, sheet6!$K:$K, 0)), "") -> Item 005 | D7: =IFERROR(INDEX(sheet6!D:D, MATCH(ROW()-1, sheet6!$K:$K, 0)), "") -> 12 | E7: =IFERROR(INDEX(sheet6!E:E, MATCH(ROW()-1, sheet6!$K:$K, 0)), "") -> dine | F7: =IFERROR(INDEX(sheet6!F:F, MATCH(ROW()-1, sheet6!$K:$K, 0)), "") -> 10 | G7: =IFERROR(INDEX(sheet6!G:G, MATCH(ROW()-1, sheet6!$K:$K, 0)), "") -> 5 | H7: =IFERROR(INDEX(sheet6!H:H, MATCH(ROW()-1, sheet6!$K:$K, 0)), "") -> 10 | I7: =IFERROR(INDEX(sheet6!I:I, MATCH(ROW()-1, sheet6!$K:$K, 0)), "") -> Storage A@A-2@B-3@L-4
A8: =IF(B8="","",ROW()-1) -> 7 | B8: =IFERROR(INDEX(sheet6!B:B, MATCH(ROW()-1, sheet6!$K:$K, 0)), "") -> ITM0004 | C8: =IFERROR(INDEX(sheet6!C:C, MATCH(ROW()-1, sheet6!$K:$K, 0)), "") -> Item 004 | D8: =IFERROR(INDEX(sheet6!D:D, MATCH(ROW()-1, sheet6!$K:$K, 0)), "") -> 0.22 | E8: =IFERROR(INDEX(sheet6!E:E, MATCH(ROW()-1, sheet6!$K:$K, 0)), "") -> dine | F8: =IFERROR(INDEX(sheet6!F:F, MATCH(ROW()-1, sheet6!$K:$K, 0)), "") -> 5 | G8: =IFERROR(INDEX(sheet6!G:G, MATCH(ROW()-1, sheet6!$K:$K, 0)), "") -> 0 | H8: =IFERROR(INDEX(sheet6!H:H, MATCH(ROW()-1, sheet6!$K:$K, 0)), "") -> 10 | I8: =IFERROR(INDEX(sheet6!I:I, MATCH(ROW()-1, sheet6!$K:$K, 0)), "") -> Storage A@A-1@B-1@L-3
A9: =IF(B9="","",ROW()-1) -> 8 | B9: =IFERROR(INDEX(sheet6!B:B, MATCH(ROW()-1, sheet6!$K:$K, 0)), "") -> ITM0002 | C9: =IFERROR(INDEX(sheet6!C:C, MATCH(ROW()-1, sheet6!$K:$K, 0)), "") -> Item 002 | D9: =IFERROR(INDEX(sheet6!D:D, MATCH(ROW()-1, sheet6!$K:$K, 0)), "") -> ml | E9: =IFERROR(INDEX(sheet6!E:E, MATCH(ROW()-1, sheet6!$K:$K, 0)), "") -> dine | F9: =IFERROR(INDEX(sheet6!F:F, MATCH(ROW()-1, sheet6!$K:$K, 0)), "") -> 10 | G9: =IFERROR(INDEX(sheet6!G:G, MATCH(ROW()-1, sheet6!$K:$K, 0)), "") -> 5 | H9: =IFERROR(INDEX(sheet6!H:H, MATCH(ROW()-1, sheet6!$K:$K, 0)), "") -> 10 | I9: =IFERROR(INDEX(sheet6!I:I, MATCH(ROW()-1, sheet6!$K:$K, 0)), "") -> Storage A@A-1@B-1@L-2
A10: =IF(B10="","",ROW()-1) -> 9 | B10: =IFERROR(INDEX(sheet6!B:B, MATCH(ROW()-1, sheet6!$K:$K, 0)), "") -> ITM0001 | C10: =IFERROR(INDEX(sheet6!C:C, MATCH(ROW()-1, sheet6!$K:$K, 0)), "") -> Item 001 | D10: =IFERROR(INDEX(sheet6!D:D, MATCH(ROW()-1, sheet6!$K:$K, 0)), "") -> kg | E10: =IFERROR(INDEX(sheet6!E:E, MATCH(ROW()-1, sheet6!$K:$K, 0)), "") -> dine | F10: =IFERROR(INDEX(sheet6!F:F, MATCH(ROW()-1, sheet6!$K:$K, 0)), "") -> 10 | G10: =IFERROR(INDEX(sheet6!G:G, MATCH(ROW()-1, sheet6!$K:$K, 0)), "") -> 10 | H10: =IFERROR(INDEX(sheet6!H:H, MATCH(ROW()-1, sheet6!$K:$K, 0)), "") -> 10 | I10: =IFERROR(INDEX(sheet6!I:I, MATCH(ROW()-1, sheet6!$K:$K, 0)), "") -> Storage A@A-1@B-1@L-1
A11: =IF(B11="","",ROW()-1) -> 10 | B11: =IFERROR(INDEX(sheet6!B:B, MATCH(ROW()-1, sheet6!$K:$K, 0)), "") -> ABC1123 | C11: =IFERROR(INDEX(sheet6!C:C, MATCH(ROW()-1, sheet6!$K:$K, 0)), "") | D11: =IFERROR(INDEX(sheet6!D:D, MATCH(ROW()-1, sheet6!$K:$K, 0)), "") | E11: =IFERROR(INDEX(sheet6!E:E, MATCH(ROW()-1, sheet6!$K:$K, 0)), "") -> dine | F11: =IFERROR(INDEX(sheet6!F:F, MATCH(ROW()-1, sheet6!$K:$K, 0)), "") -> 10 | G11: =IFERROR(INDEX(sheet6!G:G, MATCH(ROW()-1, sheet6!$K:$K, 0)), "") -> 0 | H11: =IFERROR(INDEX(sheet6!H:H, MATCH(ROW()-1, sheet6!$K:$K, 0)), "") | I11: =IFERROR(INDEX(sheet6!I:I, MATCH(ROW()-1, sheet6!$K:$K, 0)), "") -> Storage A@A-2@B-3@L-3
B12: =IFERROR(INDEX(sheet6!B:B, MATCH(ROW()-1, sheet6!$K:$K, 0)), "") | C12: =IFERROR(INDEX(sheet6!C:C, MATCH(ROW()-1, sheet6!$K:$K, 0)), "") | D12: =IFERROR(INDEX(sheet6!D:D, MATCH(ROW()-1, sheet6!$K:$K, 0)), "") | E12: =IFERROR(INDEX(sheet6!E:E, MATCH(ROW()-1, sheet6!$K:$K, 0)), "") | F12: =IFERROR(INDEX(sheet6!F:F, MATCH(ROW()-1, sheet6!$K:$K, 0)), "") | G12: =IFERROR(INDEX(sheet6!G:G, MATCH(ROW()-1, sheet6!$K:$K, 0)), "") | H12: =IFERROR(INDEX(sheet6!H:H, MATCH(ROW()-1, sheet6!$K:$K, 0)), "") | I12: =IFERROR(INDEX(sheet6!I:I, MATCH(ROW()-1, sheet6!$K:$K, 0)), "")
B13: =IFERROR(INDEX(sheet6!B:B, MATCH(ROW()-1, sheet6!$K:$K, 0)), "") | C13: =IFERROR(INDEX(sheet6!C:C, MATCH(ROW()-1, sheet6!$K:$K, 0)), "") | D13: =IFERROR(INDEX(sheet6!D:D, MATCH(ROW()-1, sheet6!$K:$K, 0)), "") | E13: =IFERROR(INDEX(sheet6!E:E, MATCH(ROW()-1, sheet6!$K:$K, 0)), "") | F13: =IFERROR(INDEX(sheet6!F:F, MATCH(ROW()-1, sheet6!$K:$K, 0)), "") | G13: =IFERROR(INDEX(sheet6!G:G, MATCH(ROW()-1, sheet6!$K:$K, 0)), "") | H13: =IFERROR(INDEX(sheet6!H:H, MATCH(ROW()-1, sheet6!$K:$K, 0)), "") | I13: =IFERROR(INDEX(sheet6!I:I, MATCH(ROW()-1, sheet6!$K:$K, 0)), "")
B14: =IFERROR(INDEX(sheet6!B:B, MATCH(ROW()-1, sheet6!$K:$K, 0)), "") | C14: =IFERROR(INDEX(sheet6!C:C, MATCH(ROW()-1, sheet6!$K:$K, 0)), "") | D14: =IFERROR(INDEX(sheet6!D:D, MATCH(ROW()-1, sheet6!$K:$K, 0)), "") | E14: =IFERROR(INDEX(sheet6!E:E, MATCH(ROW()-1, sheet6!$K:$K, 0)), "") | F14: =IFERROR(INDEX(sheet6!F:F, MATCH(ROW()-1, sheet6!$K:$K, 0)), "") | G14: =IFERROR(INDEX(sheet6!G:G, MATCH(ROW()-1, sheet6!$K:$K, 0)), "") | H14: =IFERROR(INDEX(sheet6!H:H, MATCH(ROW()-1, sheet6!$K:$K, 0)), "") | I14: =IFERROR(INDEX(sheet6!I:I, MATCH(ROW()-1, sheet6!$K:$K, 0)), "")
B15: =IFERROR(INDEX(sheet6!B:B, MATCH(ROW()-1, sheet6!$K:$K, 0)), "") | C15: =IFERROR(INDEX(sheet6!C:C, MATCH(ROW()-1, sheet6!$K:$K, 0)), "") | D15: =IFERROR(INDEX(sheet6!D:D, MATCH(ROW()-1, sheet6!$K:$K, 0)), "") | E15: =IFERROR(INDEX(sheet6!E:E, MATCH(ROW()-1, sheet6!$K:$K, 0)), "") | F15: =IFERROR(INDEX(sheet6!F:F, MATCH(ROW()-1, sheet6!$K:$K, 0)), "") | G15: =IFERROR(INDEX(sheet6!G:G, MATCH(ROW()-1, sheet6!$K:$K, 0)), "") | H15: =IFERROR(INDEX(sheet6!H:H, MATCH(ROW()-1, sheet6!$K:$K, 0)), "") | I15: =IFERROR(INDEX(sheet6!I:I, MATCH(ROW()-1, sheet6!$K:$K, 0)), "")
B16: =IFERROR(INDEX(sheet6!B:B, MATCH(ROW()-1, sheet6!$K:$K, 0)), "") | C16: =IFERROR(INDEX(sheet6!C:C, MATCH(ROW()-1, sheet6!$K:$K, 0)), "") | D16: =IFERROR(INDEX(sheet6!D:D, MATCH(ROW()-1, sheet6!$K:$K, 0)), "") | E16: =IFERROR(INDEX(sheet6!E:E, MATCH(ROW()-1, sheet6!$K:$K, 0)), "") | F16: =IFERROR(INDEX(sheet6!F:F, MATCH(ROW()-1, sheet6!$K:$K, 0)), "") | G16: =IFERROR(INDEX(sheet6!G:G, MATCH(ROW()-1, sheet6!$K:$K, 0)), "") | H16: =IFERROR(INDEX(sheet6!H:H, MATCH(ROW()-1, sheet6!$K:$K, 0)), "") | I16: =IFERROR(INDEX(sheet6!I:I, MATCH(ROW()-1, sheet6!$K:$K, 0)), "")
B17: =IFERROR(INDEX(sheet6!B:B, MATCH(ROW()-1, sheet6!$K:$K, 0)), "") | C17: =IFERROR(INDEX(sheet6!C:C, MATCH(ROW()-1, sheet6!$K:$K, 0)), "") | D17: =IFERROR(INDEX(sheet6!D:D, MATCH(ROW()-1, sheet6!$K:$K, 0)), "") | E17: =IFERROR(INDEX(sheet6!E:E, MATCH(ROW()-1, sheet6!$K:$K, 0)), "") | F17: =IFERROR(INDEX(sheet6!F:F, MATCH(ROW()-1, sheet6!$K:$K, 0)), "") | G17: =IFERROR(INDEX(sheet6!G:G, MATCH(ROW()-1, sheet6!$K:$K, 0)), "") | H17: =IFERROR(INDEX(sheet6!H:H, MATCH(ROW()-1, sheet6!$K:$K, 0)), "") | I17: =IFERROR(INDEX(sheet6!I:I, MATCH(ROW()-1, sheet6!$K:$K, 0)), "")
B18: =IFERROR(INDEX(sheet6!B:B, MATCH(ROW()-1, sheet6!$K:$K, 0)), "") | C18: =IFERROR(INDEX(sheet6!C:C, MATCH(ROW()-1, sheet6!$K:$K, 0)), "") | D18: =IFERROR(INDEX(sheet6!D:D, MATCH(ROW()-1, sheet6!$K:$K, 0)), "") | E18: =IFERROR(INDEX(sheet6!E:E, MATCH(ROW()-1, sheet6!$K:$K, 0)), "") | F18: =IFERROR(INDEX(sheet6!F:F, MATCH(ROW()-1, sheet6!$K:$K, 0)), "") | G18: =IFERROR(INDEX(sheet6!G:G, MATCH(ROW()-1, sheet6!$K:$K, 0)), "") | H18: =IFERROR(INDEX(sheet6!H:H, MATCH(ROW()-1, sheet6!$K:$K, 0)), "") | I18: =IFERROR(INDEX(sheet6!I:I, MATCH(ROW()-1, sheet6!$K:$K, 0)), "")
B19: =IFERROR(INDEX(sheet6!B:B, MATCH(ROW()-1, sheet6!$K:$K, 0)), "") | C19: =IFERROR(INDEX(sheet6!C:C, MATCH(ROW()-1, sheet6!$K:$K, 0)), "") | D19: =IFERROR(INDEX(sheet6!D:D, MATCH(ROW()-1, sheet6!$K:$K, 0)), "") | E19: =IFERROR(INDEX(sheet6!E:E, MATCH(ROW()-1, sheet6!$K:$K, 0)), "") | F19: =IFERROR(INDEX(sheet6!F:F, MATCH(ROW()-1, sheet6!$K:$K, 0)), "") | G19: =IFERROR(INDEX(sheet6!G:G, MATCH(ROW()-1, sheet6!$K:$K, 0)), "") | H19: =IFERROR(INDEX(sheet6!H:H, MATCH(ROW()-1, sheet6!$K:$K, 0)), "") | I19: =IFERROR(INDEX(sheet6!I:I, MATCH(ROW()-1, sheet6!$K:$K, 0)), "")
B20: =IFERROR(INDEX(sheet6!B:B, MATCH(ROW()-1, sheet6!$K:$K, 0)), "") | C20: =IFERROR(INDEX(sheet6!C:C, MATCH(ROW()-1, sheet6!$K:$K, 0)), "") | D20: =IFERROR(INDEX(sheet6!D:D, MATCH(ROW()-1, sheet6!$K:$K, 0)), "") | E20: =IFERROR(INDEX(sheet6!E:E, MATCH(ROW()-1, sheet6!$K:$K, 0)), "") | F20: =IFERROR(INDEX(sheet6!F:F, MATCH(ROW()-1, sheet6!$K:$K, 0)), "") | G20: =IFERROR(INDEX(sheet6!G:G, MATCH(ROW()-1, sheet6!$K:$K, 0)), "") | H20: =IFERROR(INDEX(sheet6!H:H, MATCH(ROW()-1, sheet6!$K:$K, 0)), "") | I20: =IFERROR(INDEX(sheet6!I:I, MATCH(ROW()-1, sheet6!$K:$K, 0)), "")
B21: =IFERROR(INDEX(sheet6!B:B, MATCH(ROW()-1, sheet6!$K:$K, 0)), "") | C21: =IFERROR(INDEX(sheet6!C:C, MATCH(ROW()-1, sheet6!$K:$K, 0)), "") | D21: =IFERROR(INDEX(sheet6!D:D, MATCH(ROW()-1, sheet6!$K:$K, 0)), "") | E21: =IFERROR(INDEX(sheet6!E:E, MATCH(ROW()-1, sheet6!$K:$K, 0)), "") | F21: =IFERROR(INDEX(sheet6!F:F, MATCH(ROW()-1, sheet6!$K:$K, 0)), "") | G21: =IFERROR(INDEX(sheet6!G:G, MATCH(ROW()-1, sheet6!$K:$K, 0)), "") | H21: =IFERROR(INDEX(sheet6!H:H, MATCH(ROW()-1, sheet6!$K:$K, 0)), "") | I21: =IFERROR(INDEX(sheet6!I:I, MATCH(ROW()-1, sheet6!$K:$K, 0)), "")
B22: =IFERROR(INDEX(sheet6!B:B, MATCH(ROW()-1, sheet6!$K:$K, 0)), "") | C22: =IFERROR(INDEX(sheet6!C:C, MATCH(ROW()-1, sheet6!$K:$K, 0)), "") | D22: =IFERROR(INDEX(sheet6!D:D, MATCH(ROW()-1, sheet6!$K:$K, 0)), "") | E22: =IFERROR(INDEX(sheet6!E:E, MATCH(ROW()-1, sheet6!$K:$K, 0)), "") | F22: =IFERROR(INDEX(sheet6!F:F, MATCH(ROW()-1, sheet6!$K:$K, 0)), "") | G22: =IFERROR(INDEX(sheet6!G:G, MATCH(ROW()-1, sheet6!$K:$K, 0)), "") | H22: =IFERROR(INDEX(sheet6!H:H, MATCH(ROW()-1, sheet6!$K:$K, 0)), "") | I22: =IFERROR(INDEX(sheet6!I:I, MATCH(ROW()-1, sheet6!$K:$K, 0)), "")
B23: =IFERROR(INDEX(sheet6!B:B, MATCH(ROW()-1, sheet6!$K:$K, 0)), "") | C23: =IFERROR(INDEX(sheet6!C:C, MATCH(ROW()-1, sheet6!$K:$K, 0)), "") | D23: =IFERROR(INDEX(sheet6!D:D, MATCH(ROW()-1, sheet6!$K:$K, 0)), "") | E23: =IFERROR(INDEX(sheet6!E:E, MATCH(ROW()-1, sheet6!$K:$K, 0)), "") | F23: =IFERROR(INDEX(sheet6!F:F, MATCH(ROW()-1, sheet6!$K:$K, 0)), "") | G23: =IFERROR(INDEX(sheet6!G:G, MATCH(ROW()-1, sheet6!$K:$K, 0)), "") | H23: =IFERROR(INDEX(sheet6!H:H, MATCH(ROW()-1, sheet6!$K:$K, 0)), "") | I23: =IFERROR(INDEX(sheet6!I:I, MATCH(ROW()-1, sheet6!$K:$K, 0)), "")
... B85: =IFERROR(INDEX(sheet6!B:B, MATCH(ROW()-1, sheet6!$K:$K, 0)), "") | C85: =IFERROR(INDEX(sheet6!C:C, MATCH(ROW()-1, sheet6!$K:$K, 0)), "") | D85: =IFERROR(INDEX(sheet6!D:D, MATCH(ROW()-1, sheet6!$K:$K, 0)), "") | E85: =IFERROR(INDEX(sheet6!E:E, MATCH(ROW()-1, sheet6!$K:$K, 0)), "") | F85: =IFERROR(INDEX(sheet6!F:F, MATCH(ROW()-1, sheet6!$K:$K, 0)), "") | G85: =IFERROR(INDEX(sheet6!G:G, MATCH(ROW()-1, sheet6!$K:$K, 0)), "") | H85: =IFERROR(INDEX(sheet6!H:H, MATCH(ROW()-1, sheet6!$K:$K, 0)), "") | I85: =IFERROR(INDEX(sheet6!I:I, MATCH(ROW()-1, sheet6!$K:$K, 0)), "")
B86: =IFERROR(INDEX(sheet6!B:B, MATCH(ROW()-1, sheet6!$K:$K, 0)), "") | C86: =IFERROR(VLOOKUP(B86,Data!$B:$Q,16,FALSE),"") | D86: =IFERROR(VLOOKUP(B86,Data!$B:$Q,3,FALSE),"") | E86: =IF(B86="","", IF(ROW()-1<=$Z$1, INDEX(auditor_2!F$2:F$958,$Z$1-(ROW()-2)), INDEX(auditor_1!F$2:F$785,$Z$2-(ROW()-$Z$1-2)) )) | F86: =IF(B86="","", IF(ROW()-1<=$Z$1, IF(INDEX(auditor_2!C$2:C$958,$Z$1-(ROW()-2))="", 0, INDEX(auditor_2!C$2:C$958,$Z$1-(ROW()-2)) ), IF(INDEX(auditor_1!C$2:C$785,$Z$2-(ROW()-$Z$1-2))="", 0, INDEX(auditor_1!C$2:C$785,$Z$2-(ROW()-$Z$1-2)) ) )) | G86: =IF(B86="","", IF(ROW()-1<=$Z$1, IF(INDEX(auditor_2!D$2:D$958,$Z$1-(ROW()-2))="", 0, INDEX(auditor_2!D$2:D$958,$Z$1-(ROW()-2)) ), IF(INDEX(auditor_1!D$2:D$785,$Z$2-(ROW()-$Z$1-2))="", 0, INDEX(auditor_1!D$2:D$785,$Z$2-(ROW()-$Z$1-2)) ) )) | H86: =IFERROR(VLOOKUP(B86,Data!$B:$Q,15,FALSE),"") | I86: =IF(B86="","", IF(ROW()-1<=$Z$1, INDEX(auditor_2!A$2:A$958,$Z$1-(ROW()-2)), INDEX(auditor_1!A$2:A$785,$Z$2-(ROW()-$Z$1-2)) ))
B87: =IFERROR(INDEX(sheet6!B:B, MATCH(ROW()-1, sheet6!$K:$K, 0)), "") | C87: =IFERROR(VLOOKUP(B87,Data!$B:$Q,16,FALSE),"") | D87: =IFERROR(VLOOKUP(B87,Data!$B:$Q,3,FALSE),"") | E87: =IF(B87="","", IF(ROW()-1<=$Z$1, INDEX(auditor_2!F$2:F$958,$Z$1-(ROW()-2)), INDEX(auditor_1!F$2:F$785,$Z$2-(ROW()-$Z$1-2)) )) | F87: =IF(B87="","", IF(ROW()-1<=$Z$1, IF(INDEX(auditor_2!C$2:C$958,$Z$1-(ROW()-2))="", 0, INDEX(auditor_2!C$2:C$958,$Z$1-(ROW()-2)) ), IF(INDEX(auditor_1!C$2:C$785,$Z$2-(ROW()-$Z$1-2))="", 0, INDEX(auditor_1!C$2:C$785,$Z$2-(ROW()-$Z$1-2)) ) )) | G87: =IF(B87="","", IF(ROW()-1<=$Z$1, IF(INDEX(auditor_2!D$2:D$958,$Z$1-(ROW()-2))="", 0, INDEX(auditor_2!D$2:D$958,$Z$1-(ROW()-2)) ), IF(INDEX(auditor_1!D$2:D$785,$Z$2-(ROW()-$Z$1-2))="", 0, INDEX(auditor_1!D$2:D$785,$Z$2-(ROW()-$Z$1-2)) ) )) | H87: =IFERROR(VLOOKUP(B87,Data!$B:$Q,15,FALSE),"") | I87: =IF(B87="","", IF(ROW()-1<=$Z$1, INDEX(auditor_2!A$2:A$958,$Z$1-(ROW()-2)), INDEX(auditor_1!A$2:A$785,$Z$2-(ROW()-$Z$1-2)) ))
B88: =IFERROR(INDEX(sheet6!B:B, MATCH(ROW()-1, sheet6!$K:$K, 0)), "") | C88: =IFERROR(VLOOKUP(B88,Data!$B:$Q,16,FALSE),"") | D88: =IFERROR(VLOOKUP(B88,Data!$B:$Q,3,FALSE),"") | E88: =IF(B88="","", IF(ROW()-1<=$Z$1, INDEX(auditor_2!F$2:F$958,$Z$1-(ROW()-2)), INDEX(auditor_1!F$2:F$785,$Z$2-(ROW()-$Z$1-2)) )) | F88: =IF(B88="","", IF(ROW()-1<=$Z$1, IF(INDEX(auditor_2!C$2:C$958,$Z$1-(ROW()-2))="", 0, INDEX(auditor_2!C$2:C$958,$Z$1-(ROW()-2)) ), IF(INDEX(auditor_1!C$2:C$785,$Z$2-(ROW()-$Z$1-2))="", 0, INDEX(auditor_1!C$2:C$785,$Z$2-(ROW()-$Z$1-2)) ) )) | G88: =IF(B88="","", IF(ROW()-1<=$Z$1, IF(INDEX(auditor_2!D$2:D$958,$Z$1-(ROW()-2))="", 0, INDEX(auditor_2!D$2:D$958,$Z$1-(ROW()-2)) ), IF(INDEX(auditor_1!D$2:D$785,$Z$2-(ROW()-$Z$1-2))="", 0, INDEX(auditor_1!D$2:D$785,$Z$2-(ROW()-$Z$1-2)) ) )) | H88: =IFERROR(VLOOKUP(B88,Data!$B:$Q,15,FALSE),"") | I88: =IF(B88="","", IF(ROW()-1<=$Z$1, INDEX(auditor_2!A$2:A$958,$Z$1-(ROW()-2)), INDEX(auditor_1!A$2:A$785,$Z$2-(ROW()-$Z$1-2)) ))
B89: =IFERROR(INDEX(sheet6!B:B, MATCH(ROW()-1, sheet6!$K:$K, 0)), "") | C89: =IFERROR(VLOOKUP(B89,Data!$B:$Q,16,FALSE),"") | D89: =IFERROR(VLOOKUP(B89,Data!$B:$Q,3,FALSE),"") | E89: =IF(B89="","", IF(ROW()-1<=$Z$1, INDEX(auditor_2!F$2:F$958,$Z$1-(ROW()-2)), INDEX(auditor_1!F$2:F$785,$Z$2-(ROW()-$Z$1-2)) )) | F89: =IF(B89="","", IF(ROW()-1<=$Z$1, IF(INDEX(auditor_2!C$2:C$958,$Z$1-(ROW()-2))="", 0, INDEX(auditor_2!C$2:C$958,$Z$1-(ROW()-2)) ), IF(INDEX(auditor_1!C$2:C$785,$Z$2-(ROW()-$Z$1-2))="", 0, INDEX(auditor_1!C$2:C$785,$Z$2-(ROW()-$Z$1-2)) ) )) | G89: =IF(B89="","", IF(ROW()-1<=$Z$1, IF(INDEX(auditor_2!D$2:D$958,$Z$1-(ROW()-2))="", 0, INDEX(auditor_2!D$2:D$958,$Z$1-(ROW()-2)) ), IF(INDEX(auditor_1!D$2:D$785,$Z$2-(ROW()-$Z$1-2))="", 0, INDEX(auditor_1!D$2:D$785,$Z$2-(ROW()-$Z$1-2)) ) )) | H89: =IFERROR(VLOOKUP(B89,Data!$B:$Q,15,FALSE),"") | I89: =IF(B89="","", IF(ROW()-1<=$Z$1, INDEX(auditor_2!A$2:A$958,$Z$1-(ROW()-2)), INDEX(auditor_1!A$2:A$785,$Z$2-(ROW()-$Z$1-2)) ))
B90: =IFERROR(INDEX(sheet6!B:B, MATCH(ROW()-1, sheet6!$K:$K, 0)), "") | C90: =IFERROR(VLOOKUP(B90,Data!$B:$Q,16,FALSE),"") | D90: =IFERROR(VLOOKUP(B90,Data!$B:$Q,3,FALSE),"") | E90: =IF(B90="","", IF(ROW()-1<=$Z$1, INDEX(auditor_2!F$2:F$958,$Z$1-(ROW()-2)), INDEX(auditor_1!F$2:F$785,$Z$2-(ROW()-$Z$1-2)) )) | F90: =IF(B90="","", IF(ROW()-1<=$Z$1, IF(INDEX(auditor_2!C$2:C$958,$Z$1-(ROW()-2))="", 0, INDEX(auditor_2!C$2:C$958,$Z$1-(ROW()-2)) ), IF(INDEX(auditor_1!C$2:C$785,$Z$2-(ROW()-$Z$1-2))="", 0, INDEX(auditor_1!C$2:C$785,$Z$2-(ROW()-$Z$1-2)) ) )) | G90: =IF(B90="","", IF(ROW()-1<=$Z$1, IF(INDEX(auditor_2!D$2:D$958,$Z$1-(ROW()-2))="", 0, INDEX(auditor_2!D$2:D$958,$Z$1-(ROW()-2)) ), IF(INDEX(auditor_1!D$2:D$785,$Z$2-(ROW()-$Z$1-2))="", 0, INDEX(auditor_1!D$2:D$785,$Z$2-(ROW()-$Z$1-2)) ) )) | H90: =IFERROR(VLOOKUP(B90,Data!$B:$Q,15,FALSE),"") | I90: =IF(B90="","", IF(ROW()-1<=$Z$1, INDEX(auditor_2!A$2:A$958,$Z$1-(ROW()-2)), INDEX(auditor_1!A$2:A$785,$Z$2-(ROW()-$Z$1-2)) ))
B91: =IFERROR(INDEX(sheet6!B:B, MATCH(ROW()-1, sheet6!$K:$K, 0)), "") | C91: =IFERROR(VLOOKUP(B91,Data!$B:$Q,16,FALSE),"") | D91: =IFERROR(VLOOKUP(B91,Data!$B:$Q,3,FALSE),"") | E91: =IF(B91="","", IF(ROW()-1<=$Z$1, INDEX(auditor_2!F$2:F$958,$Z$1-(ROW()-2)), INDEX(auditor_1!F$2:F$785,$Z$2-(ROW()-$Z$1-2)) )) | F91: =IF(B91="","", IF(ROW()-1<=$Z$1, IF(INDEX(auditor_2!C$2:C$958,$Z$1-(ROW()-2))="", 0, INDEX(auditor_2!C$2:C$958,$Z$1-(ROW()-2)) ), IF(INDEX(auditor_1!C$2:C$785,$Z$2-(ROW()-$Z$1-2))="", 0, INDEX(auditor_1!C$2:C$785,$Z$2-(ROW()-$Z$1-2)) ) )) | G91: =IF(B91="","", IF(ROW()-1<=$Z$1, IF(INDEX(auditor_2!D$2:D$958,$Z$1-(ROW()-2))="", 0, INDEX(auditor_2!D$2:D$958,$Z$1-(ROW()-2)) ), IF(INDEX(auditor_1!D$2:D$785,$Z$2-(ROW()-$Z$1-2))="", 0, INDEX(auditor_1!D$2:D$785,$Z$2-(ROW()-$Z$1-2)) ) )) | H91: =IFERROR(VLOOKUP(B91,Data!$B:$Q,15,FALSE),"") | I91: =IF(B91="","", IF(ROW()-1<=$Z$1, INDEX(auditor_2!A$2:A$958,$Z$1-(ROW()-2)), INDEX(auditor_1!A$2:A$785,$Z$2-(ROW()-$Z$1-2)) ))
B92: =IFERROR(INDEX(sheet6!B:B, MATCH(ROW()-1, sheet6!$K:$K, 0)), "") | C92: =IFERROR(VLOOKUP(B92,Data!$B:$Q,16,FALSE),"") | D92: =IFERROR(VLOOKUP(B92,Data!$B:$Q,3,FALSE),"") | E92: =IF(B92="","", IF(ROW()-1<=$Z$1, INDEX(auditor_2!F$2:F$958,$Z$1-(ROW()-2)), INDEX(auditor_1!F$2:F$785,$Z$2-(ROW()-$Z$1-2)) )) | F92: =IF(B92="","", IF(ROW()-1<=$Z$1, IF(INDEX(auditor_2!C$2:C$958,$Z$1-(ROW()-2))="", 0, INDEX(auditor_2!C$2:C$958,$Z$1-(ROW()-2)) ), IF(INDEX(auditor_1!C$2:C$785,$Z$2-(ROW()-$Z$1-2))="", 0, INDEX(auditor_1!C$2:C$785,$Z$2-(ROW()-$Z$1-2)) ) )) | G92: =IF(B92="","", IF(ROW()-1<=$Z$1, IF(INDEX(auditor_2!D$2:D$958,$Z$1-(ROW()-2))="", 0, INDEX(auditor_2!D$2:D$958,$Z$1-(ROW()-2)) ), IF(INDEX(auditor_1!D$2:D$785,$Z$2-(ROW()-$Z$1-2))="", 0, INDEX(auditor_1!D$2:D$785,$Z$2-(ROW()-$Z$1-2)) ) )) | H92: =IFERROR(VLOOKUP(B92,Data!$B:$Q,15,FALSE),"") | I92: =IF(B92="","", IF(ROW()-1<=$Z$1, INDEX(auditor_2!A$2:A$958,$Z$1-(ROW()-2)), INDEX(auditor_1!A$2:A$785,$Z$2-(ROW()-$Z$1-2)) ))
B93: =IFERROR(INDEX(sheet6!B:B, MATCH(ROW()-1, sheet6!$K:$K, 0)), "") | C93: =IFERROR(VLOOKUP(B93,Data!$B:$Q,16,FALSE),"") | D93: =IFERROR(VLOOKUP(B93,Data!$B:$Q,3,FALSE),"") | E93: =IF(B93="","", IF(ROW()-1<=$Z$1, INDEX(auditor_2!F$2:F$958,$Z$1-(ROW()-2)), INDEX(auditor_1!F$2:F$785,$Z$2-(ROW()-$Z$1-2)) )) | F93: =IF(B93="","", IF(ROW()-1<=$Z$1, IF(INDEX(auditor_2!C$2:C$958,$Z$1-(ROW()-2))="", 0, INDEX(auditor_2!C$2:C$958,$Z$1-(ROW()-2)) ), IF(INDEX(auditor_1!C$2:C$785,$Z$2-(ROW()-$Z$1-2))="", 0, INDEX(auditor_1!C$2:C$785,$Z$2-(ROW()-$Z$1-2)) ) )) | G93: =IF(B93="","", IF(ROW()-1<=$Z$1, IF(INDEX(auditor_2!D$2:D$958,$Z$1-(ROW()-2))="", 0, INDEX(auditor_2!D$2:D$958,$Z$1-(ROW()-2)) ), IF(INDEX(auditor_1!D$2:D$785,$Z$2-(ROW()-$Z$1-2))="", 0, INDEX(auditor_1!D$2:D$785,$Z$2-(ROW()-$Z$1-2)) ) )) | H93: =IFERROR(VLOOKUP(B93,Data!$B:$Q,15,FALSE),"") | I93: =IF(B93="","", IF(ROW()-1<=$Z$1, INDEX(auditor_2!A$2:A$958,$Z$1-(ROW()-2)), INDEX(auditor_1!A$2:A$785,$Z$2-(ROW()-$Z$1-2)) ))
B94: =IFERROR(INDEX(sheet6!B:B, MATCH(ROW()-1, sheet6!$K:$K, 0)), "") | C94: =IFERROR(VLOOKUP(B94,Data!$B:$Q,16,FALSE),"") | D94: =IFERROR(VLOOKUP(B94,Data!$B:$Q,3,FALSE),"") | E94: =IF(B94="","", IF(ROW()-1<=$Z$1, INDEX(auditor_2!F$2:F$958,$Z$1-(ROW()-2)), INDEX(auditor_1!F$2:F$785,$Z$2-(ROW()-$Z$1-2)) )) | F94: =IF(B94="","", IF(ROW()-1<=$Z$1, IF(INDEX(auditor_2!C$2:C$958,$Z$1-(ROW()-2))="", 0, INDEX(auditor_2!C$2:C$958,$Z$1-(ROW()-2)) ), IF(INDEX(auditor_1!C$2:C$785,$Z$2-(ROW()-$Z$1-2))="", 0, INDEX(auditor_1!C$2:C$785,$Z$2-(ROW()-$Z$1-2)) ) )) | G94: =IF(B94="","", IF(ROW()-1<=$Z$1, IF(INDEX(auditor_2!D$2:D$958,$Z$1-(ROW()-2))="", 0, INDEX(auditor_2!D$2:D$958,$Z$1-(ROW()-2)) ), IF(INDEX(auditor_1!D$2:D$785,$Z$2-(ROW()-$Z$1-2))="", 0, INDEX(auditor_1!D$2:D$785,$Z$2-(ROW()-$Z$1-2)) ) )) | H94: =IFERROR(VLOOKUP(B94,Data!$B:$Q,15,FALSE),"") | I94: =IF(B94="","", IF(ROW()-1<=$Z$1, INDEX(auditor_2!A$2:A$958,$Z$1-(ROW()-2)), INDEX(auditor_1!A$2:A$785,$Z$2-(ROW()-$Z$1-2)) ))
B95: =IFERROR(INDEX(sheet6!B:B, MATCH(ROW()-1, sheet6!$K:$K, 0)), "") | C95: =IFERROR(VLOOKUP(B95,Data!$B:$Q,16,FALSE),"") | D95: =IFERROR(VLOOKUP(B95,Data!$B:$Q,3,FALSE),"") | E95: =IF(B95="","", IF(ROW()-1<=$Z$1, INDEX(auditor_2!F$2:F$958,$Z$1-(ROW()-2)), INDEX(auditor_1!F$2:F$785,$Z$2-(ROW()-$Z$1-2)) )) | F95: =IF(B95="","", IF(ROW()-1<=$Z$1, IF(INDEX(auditor_2!C$2:C$958,$Z$1-(ROW()-2))="", 0, INDEX(auditor_2!C$2:C$958,$Z$1-(ROW()-2)) ), IF(INDEX(auditor_1!C$2:C$785,$Z$2-(ROW()-$Z$1-2))="", 0, INDEX(auditor_1!C$2:C$785,$Z$2-(ROW()-$Z$1-2)) ) )) | G95: =IF(B95="","", IF(ROW()-1<=$Z$1, IF(INDEX(auditor_2!D$2:D$958,$Z$1-(ROW()-2))="", 0, INDEX(auditor_2!D$2:D$958,$Z$1-(ROW()-2)) ), IF(INDEX(auditor_1!D$2:D$785,$Z$2-(ROW()-$Z$1-2))="", 0, INDEX(auditor_1!D$2:D$785,$Z$2-(ROW()-$Z$1-2)) ) )) | H95: =IFERROR(VLOOKUP(B95,Data!$B:$Q,15,FALSE),"") | I95: =IF(B95="","", IF(ROW()-1<=$Z$1, INDEX(auditor_2!A$2:A$958,$Z$1-(ROW()-2)), INDEX(auditor_1!A$2:A$785,$Z$2-(ROW()-$Z$1-2)) ))
B96: =IFERROR(INDEX(sheet6!B:B, MATCH(ROW()-1, sheet6!$K:$K, 0)), "") | C96: =IFERROR(VLOOKUP(B96,Data!$B:$Q,16,FALSE),"") | D96: =IFERROR(VLOOKUP(B96,Data!$B:$Q,3,FALSE),"") | E96: =IF(B96="","", IF(ROW()-1<=$Z$1, INDEX(auditor_2!F$2:F$958,$Z$1-(ROW()-2)), INDEX(auditor_1!F$2:F$785,$Z$2-(ROW()-$Z$1-2)) )) | F96: =IF(B96="","", IF(ROW()-1<=$Z$1, IF(INDEX(auditor_2!C$2:C$958,$Z$1-(ROW()-2))="", 0, INDEX(auditor_2!C$2:C$958,$Z$1-(ROW()-2)) ), IF(INDEX(auditor_1!C$2:C$785,$Z$2-(ROW()-$Z$1-2))="", 0, INDEX(auditor_1!C$2:C$785,$Z$2-(ROW()-$Z$1-2)) ) )) | G96: =IF(B96="","", IF(ROW()-1<=$Z$1, IF(INDEX(auditor_2!D$2:D$958,$Z$1-(ROW()-2))="", 0, INDEX(auditor_2!D$2:D$958,$Z$1-(ROW()-2)) ), IF(INDEX(auditor_1!D$2:D$785,$Z$2-(ROW()-$Z$1-2))="", 0, INDEX(auditor_1!D$2:D$785,$Z$2-(ROW()-$Z$1-2)) ) )) | H96: =IFERROR(VLOOKUP(B96,Data!$B:$Q,15,FALSE),"") | I96: =IF(B96="","", IF(ROW()-1<=$Z$1, INDEX(auditor_2!A$2:A$958,$Z$1-(ROW()-2)), INDEX(auditor_1!A$2:A$785,$Z$2-(ROW()-$Z$1-2)) ))
B97: =IFERROR(INDEX(sheet6!B:B, MATCH(ROW()-1, sheet6!$K:$K, 0)), "") | C97: =IFERROR(VLOOKUP(B97,Data!$B:$Q,16,FALSE),"") | D97: =IFERROR(VLOOKUP(B97,Data!$B:$Q,3,FALSE),"") | E97: =IF(B97="","", IF(ROW()-1<=$Z$1, INDEX(auditor_2!F$2:F$958,$Z$1-(ROW()-2)), INDEX(auditor_1!F$2:F$785,$Z$2-(ROW()-$Z$1-2)) )) | F97: =IF(B97="","", IF(ROW()-1<=$Z$1, IF(INDEX(auditor_2!C$2:C$958,$Z$1-(ROW()-2))="", 0, INDEX(auditor_2!C$2:C$958,$Z$1-(ROW()-2)) ), IF(INDEX(auditor_1!C$2:C$785,$Z$2-(ROW()-$Z$1-2))="", 0, INDEX(auditor_1!C$2:C$785,$Z$2-(ROW()-$Z$1-2)) ) )) | G97: =IF(B97="","", IF(ROW()-1<=$Z$1, IF(INDEX(auditor_2!D$2:D$958,$Z$1-(ROW()-2))="", 0, INDEX(auditor_2!D$2:D$958,$Z$1-(ROW()-2)) ), IF(INDEX(auditor_1!D$2:D$785,$Z$2-(ROW()-$Z$1-2))="", 0, INDEX(auditor_1!D$2:D$785,$Z$2-(ROW()-$Z$1-2)) ) )) | H97: =IFERROR(VLOOKUP(B97,Data!$B:$Q,15,FALSE),"") | I97: =IF(B97="","", IF(ROW()-1<=$Z$1, INDEX(auditor_2!A$2:A$958,$Z$1-(ROW()-2)), INDEX(auditor_1!A$2:A$785,$Z$2-(ROW()-$Z$1-2)) ))
... B105: =IFERROR(INDEX(sheet6!B:B, MATCH(ROW()-1, sheet6!$K:$K, 0)), "") | C105: =IFERROR(VLOOKUP(B105,Data!$B:$Q,16,FALSE),"") | D105: =IFERROR(VLOOKUP(B105,Data!$B:$Q,3,FALSE),"") | E105: =IF(B105="","", IF(ROW()-1<=$Z$1, INDEX(auditor_2!F$2:F$958,$Z$1-(ROW()-2)), INDEX(auditor_1!F$2:F$785,$Z$2-(ROW()-$Z$1-2)) )) | F105: =IF(B105="","", IF(ROW()-1<=$Z$1, IF(INDEX(auditor_2!C$2:C$958,$Z$1-(ROW()-2))="", 0, INDEX(auditor_2!C$2:C$958,$Z$1-(ROW()-2)) ), IF(INDEX(auditor_1!C$2:C$785,$Z$2-(ROW()-$Z$1-2))="", 0, INDEX(auditor_1!C$2:C$785,$Z$2-(ROW()-$Z$1-2)) ) )) | G105: =IF(B105="","", IF(ROW()-1<=$Z$1, IF(INDEX(auditor_2!D$2:D$958,$Z$1-(ROW()-2))="", 0, INDEX(auditor_2!D$2:D$958,$Z$1-(ROW()-2)) ), IF(INDEX(auditor_1!D$2:D$785,$Z$2-(ROW()-$Z$1-2))="", 0, INDEX(auditor_1!D$2:D$785,$Z$2-(ROW()-$Z$1-2)) ) )) | H105: =IFERROR(VLOOKUP(B105,Data!$B:$Q,15,FALSE),"") | I105: =IF(B105="","", IF(ROW()-1<=$Z$1, INDEX(auditor_2!A$2:A$958,$Z$1-(ROW()-2)), INDEX(auditor_1!A$2:A$785,$Z$2-(ROW()-$Z$1-2)) ))

Sheet sheet6
A1: S.No | B1: Item Code | C1: Item Name | D1: UOM | E1: Auditor Name | F1: Audited Qty | G1: Damage Qty | H1: Stock Qty | I1: Audited Location | K1: count | Z1: =COUNTIFS(auditor_2!B2:B785,"<>",auditor_1!B2:B785,"<>0") -> 6 | AB1: Total Items | AC1: =COUNTA(Data!B2:B1048576) -> 10 | AD1: =AC1/$AC$5 -> 5 | AF1: Auditor-1 | AG1: Audited Items | AH1: =COUNTIFS(auditor_1!B2:B100,"<>", auditor_1!G2:G100,"<>0") -> 5
A2: =IF(B2="","",ROW()-1) -> 1 | B2: =IF(ROW()-1<=$Z$1, INDEX(auditor_2!B$2:B$958,$Z$1-(ROW()-2)), IF(ROW()-1<=$Z$1+$Z$2, INDEX(auditor_1!B$2:B$785,$Z$2-(ROW()-$Z$1-2)), "")) -> ITM0010 | C2: =IFERROR(VLOOKUP(B2,Data!$B:$Q,16,FALSE),"") -> Item 010 | D2: =IFERROR(VLOOKUP(B2,Data!$B:$Q,3,FALSE),"") -> L | E2: =IF(B2="","", IF(ROW()-1<=$Z$1, INDEX(auditor_2!F$2:F$958,$Z$1-(ROW()-2)), INDEX(auditor_1!F$2:F$785,$Z$2-(ROW()-$Z$1-2)) )) -> egggg tttt | F2: =IF(B2="","", IF(ROW()-1<=$Z$1, IF(INDEX(auditor_2!C$2:C$958,$Z$1-(ROW()-2))="", 0, INDEX(auditor_2!C$2:C$958,$Z$1-(ROW()-2)) ), IF(INDEX(auditor_1!C$2:C$785,$Z$2-(ROW()-$Z$1-2))="", 0, INDEX(auditor_1!C$2:C$785,$Z$2-(ROW()-$Z$1-2)) ) )) -> 0 | G2: =IF(B2="","", IF(ROW()-1<=$Z$1, IF(INDEX(auditor_2!D$2:D$958,$Z$1-(ROW()-2))="", 0, INDEX(auditor_2!D$2:D$958,$Z$1-(ROW()-2)) ), IF(INDEX(auditor_1!D$2:D$785,$Z$2-(ROW()-$Z$1-2))="", 0, INDEX(auditor_1!D$2:D$785,$Z$2-(ROW()-$Z$1-2)) ) )) -> 0 | H2: =IFERROR(VLOOKUP(B2,Data!$B:$Q,15,FALSE),"") -> 10 | I2: =IF(B2="","", IF(ROW()-1<=$Z$1, INDEX(auditor_2!A$2:A$958,$Z$1-(ROW()-2)), INDEX(auditor_1!A$2:A$785,$Z$2-(ROW()-$Z$1-2)) )) -> Storage A@A-2@B-4@L-1 | K2: =IF(AND(F2<>0, B2<>""), MAX($K$1:K1)+1, "") | Z2: =COUNTIFS(auditor_1!B2:B785,"<>",auditor_2!B2:B785,"<>0") -> 6 | AB2: Audited Items | AC2: =+AH1+AH4 -> 10 | AD2: =AC3/$AC$5 -> 50 | AG2: Audited Quantity | AH2: =SUMIFS(auditor_1!C:C, auditor_1!G:G, "<>0") -> 35
A3: =IF(B3="","",ROW()-1) -> 2 | B3: =IF(ROW()-1<=$Z$1, INDEX(auditor_2!B$2:B$958,$Z$1-(ROW()-2)), IF(ROW()-1<=$Z$1+$Z$2, INDEX(auditor_1!B$2:B$785,$Z$2-(ROW()-$Z$1-2)), "")) -> ITM0009 | C3: =IFERROR(VLOOKUP(B3,Data!$B:$Q,16,FALSE),"") -> Item 009 | D3: =IFERROR(VLOOKUP(B3,Data!$B:$Q,3,FALSE),"") -> w | E3: =IF(B3="","", IF(ROW()-1<=$Z$1, INDEX(auditor_2!F$2:F$958,$Z$1-(ROW()-2)), INDEX(auditor_1!F$2:F$785,$Z$2-(ROW()-$Z$1-2)) )) -> egggg tttt | F3: =IF(B3="","", IF(ROW()-1<=$Z$1, IF(INDEX(auditor_2!C$2:C$958,$Z$1-(ROW()-2))="", 0, INDEX(auditor_2!C$2:C$958,$Z$1-(ROW()-2)) ), IF(INDEX(auditor_1!C$2:C$785,$Z$2-(ROW()-$Z$1-2))="", 0, INDEX(auditor_1!C$2:C$785,$Z$2-(ROW()-$Z$1-2)) ) )) -> 2.33 | G3: =IF(B3="","", IF(ROW()-1<=$Z$1, IF(INDEX(auditor_2!D$2:D$958,$Z$1-(ROW()-2))="", 0, INDEX(auditor_2!D$2:D$958,$Z$1-(ROW()-2)) ), IF(INDEX(auditor_1!D$2:D$785,$Z$2-(ROW()-$Z$1-2))="", 0, INDEX(auditor_1!D$2:D$785,$Z$2-(ROW()-$Z$1-2)) ) )) -> 4 | H3: =IFERROR(VLOOKUP(B3,Data!$B:$Q,15,FALSE),"") -> 10 | I3: =IF(B3="","", IF(ROW()-1<=$Z$1, INDEX(auditor_2!A$2:A$958,$Z$1-(ROW()-2)), INDEX(auditor_1!A$2:A$785,$Z$2-(ROW()-$Z$1-2)) )) -> Storage A@A-3@B-5@L-3 | K3: =IF(AND(F3<>0, B3<>""), MAX($K$1:K2)+1, "") -> 1 | AB3: Total Quantity | AC3: =SUM(Data!P2:P1048576) -> 100 | AG3: Audit Progress | AH3: =((AH1/AD1)*0.25 + (AH2/AD2)*0.75) -> 0.775
A4: =IF(B4="","",ROW()-1) -> 3 | B4: =IF(ROW()-1<=$Z$1, INDEX(auditor_2!B$2:B$958,$Z$1-(ROW()-2)), IF(ROW()-1<=$Z$1+$Z$2, INDEX(auditor_1!B$2:B$785,$Z$2-(ROW()-$Z$1-2)), "")) -> ITM0008 | C4: =IFERROR(VLOOKUP(B4,Data!$B:$Q,16,FALSE),"") -> Item 008 | D4: =IFERROR(VLOOKUP(B4,Data!$B:$Q,3,FALSE),"") -> %$ | E4: =IF(B4="","", IF(ROW()-1<=$Z$1, INDEX(auditor_2!F$2:F$958,$Z$1-(ROW()-2)), INDEX(auditor_1!F$2:F$785,$Z$2-(ROW()-$Z$1-2)) )) -> egggg tttt | F4: =IF(B4="","", IF(ROW()-1<=$Z$1, IF(INDEX(auditor_2!C$2:C$958,$Z$1-(ROW()-2))="", 0, INDEX(auditor_2!C$2:C$958,$Z$1-(ROW()-2)) ), IF(INDEX(auditor_1!C$2:C$785,$Z$2-(ROW()-$Z$1-2))="", 0, INDEX(auditor_1!C$2:C$785,$Z$2-(ROW()-$Z$1-2)) ) )) -> 2.21 | G4: =IF(B4="","", IF(ROW()-1<=$Z$1, IF(INDEX(auditor_2!D$2:D$958,$Z$1-(ROW()-2))="", 0, INDEX(auditor_2!D$2:D$958,$Z$1-(ROW()-2)) ), IF(INDEX(auditor_1!D$2:D$785,$Z$2-(ROW()-$Z$1-2))="", 0, INDEX(auditor_1!D$2:D$785,$Z$2-(ROW()-$Z$1-2)) ) )) -> 0 | H4: =IFERROR(VLOOKUP(B4,Data!$B:$Q,15,FALSE),"") -> 10 | I4: =IF(B4="","", IF(ROW()-1<=$Z$1, INDEX(auditor_2!A$2:A$958,$Z$1-(ROW()-2)), INDEX(auditor_1!A$2:A$785,$Z$2-(ROW()-$Z$1-2)) )) -> Storage A@A-2@B-3@L-5 | K4: =IF(AND(F4<>0, B4<>""), MAX($K$1:K3)+1, "") -> 2 | AB4: Audited Quantity | AC4: =+AH2+AH5 -> 61.7832 | AD4: 81.7832 | AF4: Auditor-2 | AG4: Audited Items | AH4: =COUNTIFS(auditor_2!B2:B100,"<>", auditor_2!G2:G100,"<>0") -> 5
A5: =IF(B5="","",ROW()-1) -> 4 | B5: =IF(ROW()-1<=$Z$1, INDEX(auditor_2!B$2:B$958,$Z$1-(ROW()-2)), IF(ROW()-1<=$Z$1+$Z$2, INDEX(auditor_1!B$2:B$785,$Z$2-(ROW()-$Z$1-2)), "")) -> ITM0007 | C5: =IFERROR(VLOOKUP(B5,Data!$B:$Q,16,FALSE),"") -> Item 007 | D5: =IFERROR(VLOOKUP(B5,Data!$B:$Q,3,FALSE),"") -> #$ | E5: =IF(B5="","", IF(ROW()-1<=$Z$1, INDEX(auditor_2!F$2:F$958,$Z$1-(ROW()-2)), INDEX(auditor_1!F$2:F$785,$Z$2-(ROW()-$Z$1-2)) )) -> egggg tttt | F5: =IF(B5="","", IF(ROW()-1<=$Z$1, IF(INDEX(auditor_2!C$2:C$958,$Z$1-(ROW()-2))="", 0, INDEX(auditor_2!C$2:C$958,$Z$1-(ROW()-2)) ), IF(INDEX(auditor_1!C$2:C$785,$Z$2-(ROW()-$Z$1-2))="", 0, INDEX(auditor_1!C$2:C$785,$Z$2-(ROW()-$Z$1-2)) ) )) -> 12.122 | G5: =IF(B5="","", IF(ROW()-1<=$Z$1, IF(INDEX(auditor_2!D$2:D$958,$Z$1-(ROW()-2))="", 0, INDEX(auditor_2!D$2:D$958,$Z$1-(ROW()-2)) ), IF(INDEX(auditor_1!D$2:D$785,$Z$2-(ROW()-$Z$1-2))="", 0, INDEX(auditor_1!D$2:D$785,$Z$2-(ROW()-$Z$1-2)) ) )) -> 0.2129 | H5: =IFERROR(VLOOKUP(B5,Data!$B:$Q,15,FALSE),"") -> 10 | I5: =IF(B5="","", IF(ROW()-1<=$Z$1, INDEX(auditor_2!A$2:A$958,$Z$1-(ROW()-2)), INDEX(auditor_1!A$2:A$785,$Z$2-(ROW()-$Z$1-2)) )) -> Storage A@A-3@B-5@L-2 | K5: =IF(AND(F5<>0, B5<>""), MAX($K$1:K4)+1, "") -> 3 | AB5: No of Auditors | AC5: =COUNTA(AF$1:AF$10) -> 2 | AG5: Audited Quantity | AH5: =SUMIFS(auditor_2!C:C, auditor_2!G:G, "<>0") -> 26.7832
A6: =IF(B6="","",ROW()-1) -> 5 | B6: =IF(ROW()-1<=$Z$1, INDEX(auditor_2!B$2:B$958,$Z$1-(ROW()-2)), IF(ROW()-1<=$Z$1+$Z$2, INDEX(auditor_1!B$2:B$785,$Z$2-(ROW()-$Z$1-2)), "")) -> ITM0006 | C6: =IFERROR(VLOOKUP(B6,Data!$B:$Q,16,FALSE),"") -> Item 006 | D6: =IFERROR(VLOOKUP(B6,Data!$B:$Q,3,FALSE),"") -> 0 | E6: =IF(B6="","", IF(ROW()-1<=$Z$1, INDEX(auditor_2!F$2:F$958,$Z$1-(ROW()-2)), INDEX(auditor_1!F$2:F$785,$Z$2-(ROW()-$Z$1-2)) )) -> egggg tttt | F6: =IF(B6="","", IF(ROW()-1<=$Z$1, IF(INDEX(auditor_2!C$2:C$958,$Z$1-(ROW()-2))="", 0, INDEX(auditor_2!C$2:C$958,$Z$1-(ROW()-2)) ), IF(INDEX(auditor_1!C$2:C$785,$Z$2-(ROW()-$Z$1-2))="", 0, INDEX(auditor_1!C$2:C$785,$Z$2-(ROW()-$Z$1-2)) ) )) -> 10.1212 | G6: =IF(B6="","", IF(ROW()-1<=$Z$1, IF(INDEX(auditor_2!D$2:D$958,$Z$1-(ROW()-2))="", 0, INDEX(auditor_2!D$2:D$958,$Z$1-(ROW()-2)) ), IF(INDEX(auditor_1!D$2:D$785,$Z$2-(ROW()-$Z$1-2))="", 0, INDEX(auditor_1!D$2:D$785,$Z$2-(ROW()-$Z$1-2)) ) )) -> 1 | H6: =IFERROR(VLOOKUP(B6,Data!$B:$Q,15,FALSE),"") -> 10 | I6: =IF(B6="","", IF(ROW()-1<=$Z$1, INDEX(auditor_2!A$2:A$958,$Z$1-(ROW()-2)), INDEX(auditor_1!A$2:A$785,$Z$2-(ROW()-$Z$1-2)) )) -> Storage A@A-3@B-5@L-1 | K6: =IF(AND(F6<>0, B6<>""), MAX($K$1:K5)+1, "") -> 4 | AD6: 87 | AG6: Audit Progress | AH6: =((AH1/AD1)*0.25 + (AH5/AD2)*0.75) -> 0.651748
